Workbook
Name _r: !#REF!
Name asd: !#REF!
Name Forecast: !#REF!
Name Step_1: !#REF!
Name Step_2: !#REF!
Name Step_3: !#REF!
Name Step_4: !#REF!
Name Step_5: !#REF!
Name Step_6: !#REF!
Name Step1: !#REF!
Name Step2: !#REF!
Name Step3: !#REF!
Name Step4: !#REF!
Name Step5: !#REF!
Name Step6: !#REF!

Sheet hist_inc_stmt
A1: Income Statement
A2: For the Fiscal Period Ending | B2: Reclassified 12 months Sep-30-2020 | C2: Reclassified 12 months Sep-30-2021 | D2: Reclassified 12 months Sep-30-2022 | E2: 12 months Sep-30-2023 | F2: 12 months Sep-30-2024
A3: Currency | B3: USD | C3: USD | D3: USD | E3: USD | F3: USD
A5: Revenue
A6: Other Revenue
A7: Total Revenue
A9: Cost Of Goods Sold
A10: Gross Profit
A12: Selling General & Admin Exp.
A13: R & D Exp.
A14: Depreciation & Amort.
A15: Amort. of Goodwill and Intangibles
A16: Other Operating Expense/(Income)
A18: Other Operating Exp., Total
A20: Operating Income
... A97: Note: For multiple class companies, per share items are primary class equivalent, and for foreign companies listed as primary ADRs, per share items are ADR-equivalent.

Sheet hist_bal_sht
A1: Balance Sheet
A2: Balance Sheet as of: | B2: Restated Sep-30-2020 | C2: Reclassified Sep-30-2021 | D2: Reclassified Sep-30-2022 | E2: Reclassified Sep-30-2023 | F2: 45565
A3: Currency | B3: USD | C3: USD | D3: USD | E3: USD | F3: USD
A4: ASSETS
A5: Cash And Equivalents
A6: Total Cash & ST Investments
A8: Accounts Receivable
A9: Total Receivables
A11: Other Current Assets
A12: Total Current Assets
A14: Gross Property, Plant & Equipment
A15: Accumulated Depreciation
A16: Net Property, Plant & Equipment
A18: Long-term Investments
A19: Goodwill
... A74: Note: For multiple class companies, total share counts are primary class equivalent, and for foreign companies listed as primary ADRs, total share counts are ADR-equivalent.

Sheet hist_scf
A1: Cash Flow
A2: For the Fiscal Period Ending | B2: Restated 12 months Sep-30-2020 | C2: 12 months Sep-30-2021 | D2: 12 months Sep-30-2022 | E2: Restated 12 months Sep-30-2023 | F2: 12 months Sep-30-2024
A3: Currency | B3: USD | C3: USD | D3: USD | E3: USD | F3: USD
A5: Net Income
A6: Depreciation & Amort.
A7: Amort. of Goodwill and Intangibles
A8: Depreciation & Amort., Total
A10: Other Amortization
A11: (Gain) Loss On Sale Of Invest.
A12: Asset Writedown & Restructuring Costs
A13: (Income) Loss on Equity Invest.
A14: Stock-Based Compensation
A15: Other Operating Activities
A16: Change in Acc. Receivable
A17: Change in Acc. Payable
... A59: Calculation Type

Sheet fin_model
B1: Financial Model ($ millions)
B3: Company name
B4: Ticker
B5: Share price as of valuation date
B6: Valuation date
B7: Most recent fiscal year-end date
B10: Income Statement | D10: =E10-1 -> 2020 | E10: =F10-1 -> 2021 | F10: =G10-1 -> 2022 | G10: =H10-1 -> 2023 | H10: =2024 -> 2024 | I10: =H10+1 -> 2025 | J10: =I10+1 -> 2026 | K10: =J10+1 -> 2027 | L10: =K10+1 -> 2028 | M10: =L10+1 -> 2029 | N10: =M10+1 -> 2030
B11: Revenue | D11: =hist_inc_stmt!B7 -> 0 | E11: =hist_inc_stmt!C7 -> 0 | F11: =hist_inc_stmt!D7 -> 0 | G11: =hist_inc_stmt!E7 -> 0 | H11: =hist_inc_stmt!F7 -> 0 | I11: =I99 -> #DIV/0! | J11: =J99 -> #DIV/0! | K11: =K99 -> #DIV/0! | L11: =L99 -> #DIV/0! | M11: =M99 -> #DIV/0! | N11: =N99 -> #DIV/0!
B12: Cost of goods sold (COGS) | D12: =-hist_inc_stmt!B9 -> 0 | E12: =-hist_inc_stmt!C9 -> 0 | F12: =-hist_inc_stmt!D9 -> 0 | G12: =-hist_inc_stmt!E9 -> 0 | H12: =-hist_inc_stmt!F9 -> 0 | I12: =I104 -> #DIV/0! | J12: =J104 -> #DIV/0! | K12: =K104 -> #DIV/0! | L12: =L104 -> #DIV/0! | M12: =M104 -> #DIV/0! | N12: =N104 -> #DIV/0!
B13: Gross Profit | D13: =SUM(D11:D12) -> 0 | E13: =SUM(E11:E12) -> 0 | F13: =SUM(F11:F12) -> 0 | G13: =SUM(G11:G12) -> 0 | H13: =SUM(H11:H12) -> 0 | I13: =SUM(I11:I12) -> #DIV/0! | J13: =SUM(J11:J12) -> #DIV/0! | K13: =SUM(K11:K12) -> #DIV/0! | ... N13: =SUM(N11:N12) -> #DIV/0!
B14: SG&A and other indirect expenses | D14: =-hist_inc_stmt!B18 -> 0 | E14: =-hist_inc_stmt!C18 -> 0 | F14: =-hist_inc_stmt!D18 -> 0 | G14: =-hist_inc_stmt!E18 -> 0 | H14: =-hist_inc_stmt!F18 -> 0 | I14: =I111 -> #DIV/0! | J14: =J111 -> #DIV/0! | K14: =K111 -> #DIV/0! | L14: =L111 -> #DIV/0! | M14: =M111 -> #DIV/0! | N14: =N111 -> #DIV/0!
B15: Operating Profit | D15: =(D13+D14) -> 0 | E15: =(E13+E14) -> 0 | F15: =(F13+F14) -> 0 | G15: =(G13+G14) -> 0 | H15: =(H13+H14) -> 0 | I15: =(I13+I14) -> #DIV/0! | J15: =(J13+J14) -> #DIV/0! | K15: =(K13+K14) -> #DIV/0! | ... N15: =(N13+N14) -> #DIV/0!
B16: Interest expense | D16: =hist_inc_stmt!B22 -> 0 | E16: =hist_inc_stmt!C22 -> 0 | F16: =hist_inc_stmt!D22 -> 0 | G16: =hist_inc_stmt!E22 -> 0 | H16: =hist_inc_stmt!F22 -> 0 | I16: =I118 -> #DIV/0! | J16: =J118 -> #DIV/0! | K16: =K118 -> #DIV/0! | L16: =L118 -> #DIV/0! | M16: =M118 -> #DIV/0! | N16: =N118 -> #DIV/0!
B17: Other non-operating income (expense) except interest expense & unusual | D17: =SUM(hist_inc_stmt!B26:B28)+hist_inc_stmt!B23 -> 0 | E17: =SUM(hist_inc_stmt!C26:C28)+hist_inc_stmt!C23 -> 0 | F17: =SUM(hist_inc_stmt!D26:D28)+hist_inc_stmt!D23 -> 0 | G17: =SUM(hist_inc_stmt!E26:E28)+hist_inc_stmt!E23 -> 0 | H17: =SUM(hist_inc_stmt!F26:F28)+hist_inc_stmt!F23 -> 0 | I17: =I123 -> #DIV/0! | J17: =J123 -> #DIV/0! | K17: =K123 -> #DIV/0! | L17: =L123 -> #DIV/0! | M17: =M123 -> #DIV/0! | N17: =N123 -> #DIV/0!
B18: Unusual items | D18: =SUM(hist_inc_stmt!B31:B35) -> 0 | E18: =SUM(hist_inc_stmt!C31:C35) -> 0 | F18: =SUM(hist_inc_stmt!D31:D35) -> 0 | G18: =SUM(hist_inc_stmt!E31:E35) -> 0 | H18: =SUM(hist_inc_stmt!F31:F35) -> 0 | I18: =I129 -> #DIV/0! | J18: =J129 -> #DIV/0! | K18: =K129 -> #DIV/0! | L18: =L129 -> #DIV/0! | M18: =M129 -> #DIV/0! | N18: =N129 -> #DIV/0!
B19: Earnings Before Tax | D19: =SUM(D15:D18) -> 0 | E19: =SUM(E15:E18) -> 0 | F19: =SUM(F15:F18) -> 0 | G19: =SUM(G15:G18) -> 0 | H19: =SUM(H15:H18) -> 0 | I19: =SUM(I15:I18) -> #DIV/0! | J19: =SUM(J15:J18) -> #DIV/0! | K19: =SUM(K15:K18) -> #DIV/0! | ... N19: =SUM(N15:N18) -> #DIV/0!
B20: Taxes | D20: =-hist_inc_stmt!B38 -> 0 | E20: =-hist_inc_stmt!C38 -> 0 | F20: =-hist_inc_stmt!D38 -> 0 | G20: =-hist_inc_stmt!E38 -> 0 | H20: =-hist_inc_stmt!F38 -> 0 | I20: =I133 -> #DIV/0! | J20: =J133 -> #DIV/0! | K20: =K133 -> #DIV/0! | L20: =L133 -> #DIV/0! | M20: =M133 -> #DIV/0! | N20: =N133 -> #DIV/0!
B21: Net income from continuing operations | D21: =SUM(D19:D20) -> 0 | E21: =SUM(E19:E20) -> 0 | F21: =SUM(F19:F20) -> 0 | G21: =SUM(G19:G20) -> 0 | H21: =SUM(H19:H20) -> 0 | I21: =I19+I20 -> #DIV/0! | J21: =J19+J20 -> #DIV/0! | K21: =K19+K20 -> #DIV/0! | L21: =L19+L20 -> #DIV/0! | M21: =M19+M20 -> #DIV/0! | N21: =N19+N20 -> #DIV/0!
B22: Other considerations (discontinued, noncontrolling, preferred dividends, etc.) | D22: =hist_inc_stmt!B45 -> 0 | E22: =hist_inc_stmt!C45 -> 0 | F22: =hist_inc_stmt!D45 -> 0 | G22: =hist_inc_stmt!E45 -> 0 | H22: =hist_inc_stmt!F45 -> 0 | I22: =I139 -> #DIV/0! | J22: =J139 -> #DIV/0! | K22: =K139 -> #DIV/0! | L22: =L139 -> #DIV/0! | M22: =M139 -> #DIV/0! | N22: =N139 -> #DIV/0!
B23: Net income | D23: =SUM(D21:D22) -> 0 | E23: =SUM(E21:E22) -> 0 | F23: =SUM(F21:F22) -> 0 | G23: =SUM(G21:G22) -> 0 | H23: =SUM(H21:H22) -> 0 | I23: =SUM(I21:I22) -> #DIV/0! | J23: =SUM(J21:J22) -> #DIV/0! | K23: =SUM(K21:K22) -> #DIV/0! | ... N23: =SUM(N21:N22) -> #DIV/0!
B26: Balance Sheet | D26: =D10 -> 2020 | E26: =E10 -> 2021 | F26: =F10 -> 2022 | G26: =G10 -> 2023 | H26: =H10 -> 2024 | I26: =H26+1 -> 2025 | J26: =I26+1 -> 2026 | K26: =J26+1 -> 2027 | L26: =K26+1 -> 2028 | M26: =L26+1 -> 2029 | N26: =M26+1 -> 2030
B27: Assets
B28: Cash & equivalents | D28: =hist_bal_sht!B5 -> 0 | E28: =hist_bal_sht!C5 -> 0 | F28: =hist_bal_sht!D5 -> 0 | G28: =hist_bal_sht!E5 -> 0 | H28: =hist_bal_sht!F5 -> 0 | I28: =I290 -> #DIV/0! | J28: =J290 -> #DIV/0! | K28: =K290 -> #DIV/0! | L28: =L290 -> #DIV/0! | M28: =M290 -> #DIV/0! | N28: =N290 -> #DIV/0!
B29: Other nonoperating current assets | D29: =hist_bal_sht!B11 -> 0 | E29: =hist_bal_sht!C11 -> 0 | F29: =hist_bal_sht!D11 -> 0 | G29: =hist_bal_sht!E11 -> 0 | H29: =hist_bal_sht!F11 -> 0 | I29: =I147 -> #DIV/0! | J29: =J147 -> #DIV/0! | K29: =K147 -> #DIV/0! | L29: =L147 -> #DIV/0! | M29: =M147 -> #DIV/0! | N29: =N147 -> #DIV/0!
B30: Accounts receivable | D30: =hist_bal_sht!B8 -> 0 | E30: =hist_bal_sht!C8 -> 0 | F30: =hist_bal_sht!D8 -> 0 | G30: =hist_bal_sht!E8 -> 0 | H30: =hist_bal_sht!F8 -> 0 | I30: =I152 -> #DIV/0! | J30: =J152 -> #DIV/0! | K30: =K152 -> #DIV/0! | L30: =L152 -> #DIV/0! | M30: =M152 -> #DIV/0! | N30: =N152 -> #DIV/0!
B31: Inventory | D31: 0 | E31: 0 | F31: 0 | G31: 0 | H31: 0 | I31: =I157 -> 0 | J31: =J157 -> #DIV/0! | K31: =K157 -> #DIV/0! | L31: =L157 -> #DIV/0! | M31: =M157 -> #DIV/0! | N31: =N157 -> #DIV/0!
B32: Other operating current assets | D32: 0 | E32: 0 | F32: 0 | G32: 0 | H32: 0 | I32: =I163 -> #DIV/0! | J32: =J163 -> #DIV/0! | K32: =K163 -> #DIV/0! | L32: =L163 -> #DIV/0! | M32: =M163 -> #DIV/0! | N32: =N163 -> #DIV/0!
B33: Current Assets | D33: =SUM(D28:D32) -> 0 | E33: =SUM(E28:E32) -> 0 | F33: =SUM(F28:F32) -> 0 | G33: =SUM(G28:G32) -> 0 | H33: =SUM(H28:H32) -> 0 | I33: =SUM(I28:I32) -> #DIV/0! | J33: =SUM(J28:J32) -> #DIV/0! | K33: =SUM(K28:K32) -> #DIV/0! | ... N33: =SUM(N28:N32) -> #DIV/0!
B34: PP&E | D34: =hist_bal_sht!B16 -> 0 | E34: =hist_bal_sht!C16 -> 0 | F34: =hist_bal_sht!D16 -> 0 | G34: =hist_bal_sht!E16 -> 0 | H34: =hist_bal_sht!F16 -> 0 | I34: =I169 -> #DIV/0! | J34: =J169 -> #DIV/0! | K34: =K169 -> #DIV/0! | L34: =L169 -> #DIV/0! | M34: =M169 -> #DIV/0! | N34: =N169 -> #DIV/0!
B35: Other long-term assets | D35: =hist_bal_sht!B23-hist_bal_sht!B16-hist_bal_sht!B12 -> 0 | E35: =hist_bal_sht!C23-hist_bal_sht!C16-hist_bal_sht!C12 -> 0 | F35: =hist_bal_sht!D23-hist_bal_sht!D16-hist_bal_sht!D12 -> 0 | G35: =hist_bal_sht!E23-hist_bal_sht!E16-hist_bal_sht!E12 -> 0 | H35: =hist_bal_sht!F23-hist_bal_sht!F16-hist_bal_sht!F12 -> 0 | I35: =I180 -> #DIV/0! | J35: =J180 -> #DIV/0! | K35: =K180 -> #DIV/0! | L35: =L180 -> #DIV/0! | M35: =M180 -> #DIV/0! | N35: =N180 -> #DIV/0!
B36: Long-term Assets | D36: =SUM(D34:D35) -> 0 | E36: =SUM(E34:E35) -> 0 | F36: =SUM(F34:F35) -> 0 | G36: =SUM(G34:G35) -> 0 | H36: =SUM(H34:H35) -> 0 | I36: =SUM(I34:I35) -> #DIV/0! | J36: =SUM(J34:J35) -> #DIV/0! | K36: =SUM(K34:K35) -> #DIV/0! | ... N36: =SUM(N34:N35) -> #DIV/0!
B37: Total Assets | D37: =D33+D36 -> 0 | E37: =E33+E36 -> 0 | F37: =F33+F36 -> 0 | G37: =G33+G36 -> 0 | H37: =H33+H36 -> 0 | I37: =I33+I36 -> #DIV/0! | J37: =J33+J36 -> #DIV/0! | K37: =K33+K36 -> #DIV/0! | ... N37: =N33+N36 -> #DIV/0!
B39: Liabilities
B40: Accounts payable | D40: =hist_bal_sht!B26 -> 0 | E40: =hist_bal_sht!C26 -> 0 | F40: =hist_bal_sht!D26 -> 0 | G40: =hist_bal_sht!E26 -> 0 | H40: =hist_bal_sht!F26 -> 0 | I40: =I188 -> #DIV/0! | J40: =J188 -> #DIV/0! | K40: =K188 -> #DIV/0! | L40: =L188 -> #DIV/0! | M40: =M188 -> #DIV/0! | N40: =N188 -> #DIV/0!
B41: Short-term debt | D41: 0 | E41: 0 | F41: 0 | G41: 0 | H41: 0 | I41: =I193 -> 0 | J41: =J193 -> 0 | K41: =K193 -> 0 | L41: =L193 -> 0 | M41: =M193 -> 0 | N41: =N193 -> 0
B42: Current portion of long-term debt | D42: =IF(hist_bal_sht!B28 = "-","0",hist_bal_sht!B28) -> 0 | E42: =IF(hist_bal_sht!C28 = "-","0",hist_bal_sht!C28) -> 0 | F42: =IF(hist_bal_sht!D28 = "-","0",hist_bal_sht!D28) -> 0 | G42: =IF(hist_bal_sht!E28 = "-","0",hist_bal_sht!E28) -> 0 | H42: =IF(hist_bal_sht!F28 = "-","0",hist_bal_sht!F28) -> 0 | I42: =I197 -> 400 | J42: =J197 -> 469.5 | K42: =K197 -> 0 | L42: =L197 -> 0 | M42: =M197 -> 0 | N42: =N197 -> 847.5
B43: Other current liabilities | D43: =hist_bal_sht!B32-hist_bal_sht!B26 -> 0 | E43: =hist_bal_sht!C32-hist_bal_sht!C26 -> 0 | F43: =hist_bal_sht!D32-hist_bal_sht!D26 -> 0 | G43: =hist_bal_sht!E32-hist_bal_sht!E26 -> 0 | H43: =hist_bal_sht!F32-hist_bal_sht!F26 -> 0 | I43: =I203 -> #DIV/0! | J43: =J203 -> #DIV/0! | K43: =K203 -> #DIV/0! | L43: =L203 -> #DIV/0! | M43: =M203 -> #DIV/0! | N43: =N203 -> #DIV/0!
B44: Current Liabilities | D44: =SUM(D40:D43)-D42 -> 0 | E44: =SUM(E40:E43)-E42 -> 0 | F44: =SUM(F40:F43)-F42 -> 0 | G44: =SUM(G40:G43)-G42 -> 0 | H44: =SUM(H40:H43)-H42 -> 0 | I44: =SUM(I40:I43) -> #DIV/0! | J44: =SUM(J40:J43) -> #DIV/0! | K44: =SUM(K40:K43) -> #DIV/0! | L44: =SUM(L40:L43) -> #DIV/0! | M44: =SUM(M40:M43) -> #DIV/0! | N44: =SUM(N40:N43) -> #DIV/0!
B45: Long-term debt | D45: =hist_bal_sht!B34 -> 0 | E45: =hist_bal_sht!C34 -> 0 | F45: =hist_bal_sht!D34 -> 0 | G45: =hist_bal_sht!E34 -> 0 | H45: =hist_bal_sht!F34 -> 0 | I45: =I210 -> #DIV/0! | J45: =J210 -> #DIV/0! | K45: =K210 -> #DIV/0! | L45: =L210 -> #DIV/0! | M45: =M210 -> #DIV/0! | N45: =N210 -> #DIV/0!
B46: Other long-term liabilities | D46: =SUM(hist_bal_sht!B35:B37) -> 0 | E46: =SUM(hist_bal_sht!C35:C37) -> 0 | F46: =SUM(hist_bal_sht!D35:D37) -> 0 | G46: =SUM(hist_bal_sht!E35:E37) -> 0 | H46: =SUM(hist_bal_sht!F35:F37) -> 0 | I46: =I224 -> #DIV/0! | J46: =J224 -> #DIV/0! | K46: =K224 -> #DIV/0! | L46: =L224 -> #DIV/0! | M46: =M224 -> #DIV/0! | N46: =N224 -> #DIV/0!
...

Sheet model_drivers
B2: Last Historic Year | C2: Forecast year 1 | D2: Forecast year 2 | E2: Forecast year 3 | F2: Forecast year 4 | G2: Forecast year 5 | H2: Forecast year 6
A3: Income statement
A4: Revenue growth rate | B4: =fin_model!X97 -> #DIV/0! | C4: =fin_model!I98 -> #DIV/0! | D4: =fin_model!J98 -> #DIV/0! | E4: =fin_model!K98 -> #DIV/0! | F4: =fin_model!L98 -> #DIV/0! | G4: =fin_model!M98 -> #DIV/0! | H4: =fin_model!N98 -> #DIV/0!
A5: COGS to sales | B5: =fin_model!H12/fin_model!H11 -> #DIV/0! | C5: =fin_model!I12/fin_model!I11 -> #DIV/0! | D5: =fin_model!J12/fin_model!J11 -> #DIV/0! | E5: =fin_model!K12/fin_model!K11 -> #DIV/0! | F5: =fin_model!L12/fin_model!L11 -> #DIV/0! | G5: =fin_model!M12/fin_model!M11 -> #DIV/0! | H5: =fin_model!N12/fin_model!N11 -> #DIV/0!
A6: SG&A & other indirect expenses to sales | B6: =fin_model!H14/fin_model!H11 -> #DIV/0! | C6: =fin_model!I14/fin_model!I11 -> #DIV/0! | D6: =fin_model!J14/fin_model!J11 -> #DIV/0! | E6: =fin_model!K14/fin_model!K11 -> #DIV/0! | F6: =fin_model!L14/fin_model!L11 -> #DIV/0! | G6: =fin_model!M14/fin_model!M11 -> #DIV/0! | H6: =fin_model!N14/fin_model!N11 -> #DIV/0!
A7: Implied interest rate | B7: =fin_model!$I116 -> #DIV/0! | C7: =fin_model!$I116 -> #DIV/0! | D7: =fin_model!$I116 -> #DIV/0! | E7: =fin_model!$I116 -> #DIV/0! | F7: =fin_model!$I116 -> #DIV/0! | G7: =fin_model!$I116 -> #DIV/0! | H7: =fin_model!$I116 -> #DIV/0!
A8: All other non-operating income (expense) to sales | B8: =fin_model!H17/fin_model!H11 -> #DIV/0! | C8: =fin_model!I17/fin_model!I11 -> #DIV/0! | D8: =fin_model!J17/fin_model!J11 -> #DIV/0! | E8: =fin_model!K17/fin_model!K11 -> #DIV/0! | F8: =fin_model!L17/fin_model!L11 -> #DIV/0! | G8: =fin_model!M17/fin_model!M11 -> #DIV/0! | H8: =fin_model!N17/fin_model!N11 -> #DIV/0!
A9: Unusual items to sales | B9: =fin_model!H18/fin_model!H11 -> #DIV/0! | C9: =fin_model!I18/fin_model!I11 -> #DIV/0! | D9: =fin_model!J18/fin_model!J11 -> #DIV/0! | E9: =fin_model!K18/fin_model!K11 -> #DIV/0! | F9: =fin_model!L18/fin_model!L11 -> #DIV/0! | G9: =fin_model!M18/fin_model!M11 -> #DIV/0! | H9: =fin_model!N18/fin_model!N11 -> #DIV/0!
A10: Effective tax rate | B10: =fin_model!$I132 -> #DIV/0! | C10: =fin_model!$I132 -> #DIV/0! | D10: =fin_model!$I132 -> #DIV/0! | E10: =fin_model!$I132 -> #DIV/0! | F10: =fin_model!$I132 -> #DIV/0! | G10: =fin_model!$I132 -> #DIV/0! | H10: =fin_model!$I132 -> #DIV/0!
A11: Other considerations to sales | B11: =fin_model!H22/fin_model!H11 -> #DIV/0! | C11: =fin_model!I22/fin_model!I11 -> #DIV/0! | D11: =fin_model!J22/fin_model!J11 -> #DIV/0! | E11: =fin_model!K22/fin_model!K11 -> #DIV/0! | F11: =fin_model!L22/fin_model!L11 -> #DIV/0! | G11: =fin_model!M22/fin_model!M11 -> #DIV/0! | H11: =fin_model!N22/fin_model!N11 -> #DIV/0!
A12: Balance sheet
A13: Other nonoperating current assets to sales | B13: =fin_model!H29/fin_model!H11 -> #DIV/0! | C13: =fin_model!I29/fin_model!I11 -> #DIV/0! | D13: =fin_model!J29/fin_model!J11 -> #DIV/0! | E13: =fin_model!K29/fin_model!K11 -> #DIV/0! | F13: =fin_model!L29/fin_model!L11 -> #DIV/0! | G13: =fin_model!M29/fin_model!M11 -> #DIV/0! | H13: =fin_model!N29/fin_model!N11 -> #DIV/0!
A14: Receivables to sales | B14: =fin_model!H30/fin_model!H11 -> #DIV/0! | C14: =fin_model!I30/fin_model!I11 -> #DIV/0! | D14: =fin_model!J30/fin_model!J11 -> #DIV/0! | E14: =fin_model!K30/fin_model!K11 -> #DIV/0! | F14: =fin_model!L30/fin_model!L11 -> #DIV/0! | G14: =fin_model!M30/fin_model!M11 -> #DIV/0! | H14: =fin_model!N30/fin_model!N11 -> #DIV/0!
A15: Inventory to COGS | B15: =fin_model!H31/fin_model!H12 -> #DIV/0! | C15: =fin_model!I31/fin_model!I12 -> #DIV/0! | D15: =fin_model!J31/fin_model!J12 -> #DIV/0! | E15: =fin_model!K31/fin_model!K12 -> #DIV/0! | F15: =fin_model!L31/fin_model!L12 -> #DIV/0! | G15: =fin_model!M31/fin_model!M12 -> #DIV/0! | H15: =fin_model!N31/fin_model!N12 -> #DIV/0!
A16: Other operating current assets to sales | B16: =fin_model!H32/fin_model!H11 -> #DIV/0! | C16: =fin_model!I32/fin_model!I11 -> #DIV/0! | D16: =fin_model!J32/fin_model!J11 -> #DIV/0! | E16: =fin_model!K32/fin_model!K11 -> #DIV/0! | F16: =fin_model!L32/fin_model!L11 -> #DIV/0! | G16: =fin_model!M32/fin_model!M11 -> #DIV/0! | H16: =fin_model!N32/fin_model!N11 -> #DIV/0!
A17: Depreciation to sales (relevant for PP&E and SCF) | B17: =fin_model!H60/fin_model!H11 -> #DIV/0! | C17: =fin_model!I60/fin_model!I11 -> #DIV/0! | D17: =fin_model!J60/fin_model!J11 -> #DIV/0! | E17: =fin_model!K60/fin_model!K11 -> #DIV/0! | F17: =fin_model!L60/fin_model!L11 -> #DIV/0! | G17: =fin_model!M60/fin_model!M11 -> #DIV/0! | H17: =fin_model!N60/fin_model!N11 -> #DIV/0!
A18: CAPEX CF to sales (relevant for PP&E and SCF) - CF, so should be negative | B18: =fin_model!H66/fin_model!H11 -> #DIV/0! | C18: =fin_model!I66/fin_model!I11 -> #DIV/0! | D18: =fin_model!J66/fin_model!J11 -> #DIV/0! | E18: =fin_model!K66/fin_model!K11 -> #DIV/0! | F18: =fin_model!L66/fin_model!L11 -> #DIV/0! | G18: =fin_model!M66/fin_model!M11 -> #DIV/0! | H18: =fin_model!N66/fin_model!N11 -> #DIV/0!
A19: Other long-term assets to sales | B19: =fin_model!H35/fin_model!H11 -> #DIV/0! | C19: =fin_model!I35/fin_model!I11 -> #DIV/0! | D19: =fin_model!J35/fin_model!J11 -> #DIV/0! | E19: =fin_model!K35/fin_model!K11 -> #DIV/0! | F19: =fin_model!L35/fin_model!L11 -> #DIV/0! | G19: =fin_model!M35/fin_model!M11 -> #DIV/0! | H19: =fin_model!N35/fin_model!N11 -> #DIV/0!
A20: Payables to COGS | B20: =fin_model!H40/fin_model!H12 -> #DIV/0! | C20: =fin_model!I40/fin_model!I12 -> #DIV/0! | D20: =fin_model!J40/fin_model!J12 -> #DIV/0! | E20: =fin_model!K40/fin_model!K12 -> #DIV/0! | F20: =fin_model!L40/fin_model!L12 -> #DIV/0! | G20: =fin_model!M40/fin_model!M12 -> #DIV/0! | H20: =fin_model!N40/fin_model!N12 -> #DIV/0!
A21: Amount of short-term debt | B21: =fin_model!H41 -> 0 | C21: =fin_model!I41 -> 0 | D21: =fin_model!J41 -> 0 | E21: =fin_model!K41 -> 0 | F21: =fin_model!L41 -> 0 | G21: =fin_model!M41 -> 0 | H21: =fin_model!N41 -> 0
A22: Amount of current portion of long-term debt | B22: =fin_model!H42 -> 0 | C22: =fin_model!I42 -> 400 | D22: =fin_model!J42 -> 469.5 | E22: =fin_model!K42 -> 0 | F22: =fin_model!L42 -> 0 | G22: =fin_model!M42 -> 0 | H22: =fin_model!N42 -> 847.5
A23: Other current liabilities to sales | B23: =fin_model!H43/fin_model!H11 -> #DIV/0! | C23: =fin_model!I43/fin_model!I11 -> #DIV/0! | D23: =fin_model!J43/fin_model!J11 -> #DIV/0! | E23: =fin_model!K43/fin_model!K11 -> #DIV/0! | F23: =fin_model!L43/fin_model!L11 -> #DIV/0! | G23: =fin_model!M43/fin_model!M11 -> #DIV/0! | H23: =fin_model!N43/fin_model!N11 -> #DIV/0!
A24: Amount of long-term debt in LT liabilities | B24: =fin_model!H45 -> 0 | C24: =fin_model!I45 -> #DIV/0! | D24: =fin_model!J45 -> #DIV/0! | E24: =fin_model!K45 -> #DIV/0! | F24: =fin_model!L45 -> #DIV/0! | G24: =fin_model!M45 -> #DIV/0! | H24: =fin_model!N45 -> #DIV/0!
A25: Other long-term liabilities to sales | B25: =fin_model!H46/fin_model!H11 -> #DIV/0! | C25: =fin_model!I46/fin_model!I11 -> #DIV/0! | D25: =fin_model!J46/fin_model!J11 -> #DIV/0! | E25: =fin_model!K46/fin_model!K11 -> #DIV/0! | F25: =fin_model!L46/fin_model!L11 -> #DIV/0! | G25: =fin_model!M46/fin_model!M11 -> #DIV/0! | H25: =fin_model!N46/fin_model!N11 -> #DIV/0!
A26: Dividend cash flow in first forecast year | B26: =fin_model!H73 -> 0 | C26: =fin_model!I73 -> #DIV/0!
A27: Dividend growth rate | D27: =(fin_model!J73-fin_model!I73)/fin_model!I73 -> #DIV/0! | E27: =(fin_model!K73-fin_model!J73)/fin_model!J73 -> #DIV/0! | F27: =(fin_model!L73-fin_model!K73)/fin_model!K73 -> #DIV/0! | G27: =(fin_model!M73-fin_model!L73)/fin_model!L73 -> #DIV/0! | H27: =(fin_model!N73-fin_model!M73)/fin_model!M73 -> #DIV/0!
A28: Net equity issued (repurchased) to sales | B28: =fin_model!H72/fin_model!H11 -> #DIV/0! | C28: =fin_model!I72/fin_model!I11 -> #DIV/0! | D28: =fin_model!J72/fin_model!J11 -> #DIV/0! | E28: =fin_model!K72/fin_model!K11 -> #DIV/0! | F28: =fin_model!L72/fin_model!L11 -> #DIV/0! | G28: =fin_model!M72/fin_model!M11 -> #DIV/0! | H28: =fin_model!N72/fin_model!N11 -> #DIV/0!
A29: All other relevant equity change items to sales | B29: =fin_model!H315/fin_model!H11 -> #DIV/0! | C29: =fin_model!I315/fin_model!I11 -> #DIV/0! | D29: =fin_model!J315/fin_model!J11 -> #DIV/0! | E29: =fin_model!K315/fin_model!K11 -> #DIV/0! | F29: =fin_model!L315/fin_model!L11 -> #DIV/0! | G29: =fin_model!M315/fin_model!M11 -> #DIV/0! | H29: =fin_model!N315/fin_model!N11 -> #DIV/0!
A30: Statement of cash flows
A31: Amortization to sales | B31: =fin_model!H61/fin_model!H11 -> #DIV/0! | C31: =fin_model!I61/fin_model!I11 -> #DIV/0! | D31: =fin_model!J61/fin_model!J11 -> #DIV/0! | E31: =fin_model!K61/fin_model!K11 -> #DIV/0! | F31: =fin_model!L61/fin_model!L11 -> #DIV/0! | G31: =fin_model!M61/fin_model!M11 -> #DIV/0! | H31: =fin_model!N61/fin_model!N11 -> #DIV/0!
A32: Other operating cash flow to sales | B32: =fin_model!H62/fin_model!H11 -> #DIV/0! | C32: =fin_model!I62/fin_model!I11 -> #DIV/0! | D32: =fin_model!J62/fin_model!J11 -> #DIV/0! | E32: =fin_model!K62/fin_model!K11 -> #DIV/0! | F32: =fin_model!L62/fin_model!L11 -> #DIV/0! | G32: =fin_model!M62/fin_model!M11 -> #DIV/0! | H32: =fin_model!N62/fin_model!N11 -> #DIV/0!
A33: Other investing cash flow to sales | B33: =fin_model!H67/fin_model!H11 -> #DIV/0! | C33: =fin_model!I67/fin_model!I11 -> #DIV/0! | D33: =fin_model!J67/fin_model!J11 -> #DIV/0! | E33: =fin_model!K67/fin_model!K11 -> #DIV/0! | F33: =fin_model!L67/fin_model!L11 -> #DIV/0! | G33: =fin_model!M67/fin_model!M11 -> #DIV/0! | H33: =fin_model!N67/fin_model!N11 -> #DIV/0!
A34: Other financing cash flow to sales | B34: =fin_model!H74/fin_model!H11 -> #DIV/0! | C34: =fin_model!I74/fin_model!I11 -> #DIV/0! | D34: =fin_model!J74/fin_model!J11 -> #DIV/0! | E34: =fin_model!K74/fin_model!K11 -> #DIV/0! | F34: =fin_model!L74/fin_model!L11 -> #DIV/0! | G34: =fin_model!M74/fin_model!M11 -> #DIV/0! | H34: =fin_model!N74/fin_model!N11 -> #DIV/0!

Sheet fsa_measures
A3: Financial statement analysis for firm: historical & forecast
B4: Historical period | G4: Forecast period
B5: =fin_model!D10 -> 2020 | C5: =B5+1 -> 2021 | D5: =C5+1 -> 2022 | E5: =D5+1 -> 2023 | F5: =E5+1 -> 2024 | G5: =F5+1 -> 2025 | H5: =G5+1 -> 2026 | I5: =H5+1 -> 2027 | J5: =I5+1 -> 2028 | ... L5: =K5+1 -> 2030
B6: Liquidity
A7: Current ratio | B7: =fin_model!D33/fin_model!D44 -> #DIV/0! | C7: =fin_model!E33/fin_model!E44 -> #DIV/0! | D7: =fin_model!F33/fin_model!F44 -> #DIV/0! | E7: =fin_model!G33/fin_model!G44 -> #DIV/0! | F7: =fin_model!H33/fin_model!H44 -> #DIV/0! | G7: =fin_model!I33/fin_model!I44 -> #DIV/0! | H7: =fin_model!J33/fin_model!J44 -> #DIV/0! | I7: =fin_model!K33/fin_model!K44 -> #DIV/0! | ... L7: =fin_model!N33/fin_model!N44 -> #DIV/0!
A8: Quick ratio | B8: =(fin_model!D33-fin_model!D31)/fin_model!D44 -> #DIV/0! | C8: =(fin_model!E33-fin_model!E31)/fin_model!E44 -> #DIV/0! | D8: =(fin_model!F33-fin_model!F31)/fin_model!F44 -> #DIV/0! | E8: =(fin_model!G33-fin_model!G31)/fin_model!G44 -> #DIV/0! | F8: =(fin_model!H33-fin_model!H31)/fin_model!H44 -> #DIV/0! | G8: =(fin_model!I33-fin_model!I31)/fin_model!I44 -> #DIV/0! | H8: =(fin_model!J33-fin_model!J31)/fin_model!J44 -> #DIV/0! | I8: =(fin_model!K33-fin_model!K31)/fin_model!K44 -> #DIV/0! | ... L8: =(fin_model!N33-fin_model!N31)/fin_model!N44 -> #DIV/0!
B9: Solvency
A10: Times interest earned (from EBIT) | B10: =-(fin_model!D15/fin_model!D16) -> #DIV/0! | C10: =-(fin_model!E15/fin_model!E16) -> #DIV/0! | D10: =-(fin_model!F15/fin_model!F16) -> #DIV/0! | E10: =-(fin_model!G15/fin_model!G16) -> #DIV/0! | F10: =-(fin_model!H15/fin_model!H16) -> #DIV/0! | G10: =-(fin_model!I15/fin_model!I16) -> #DIV/0! | H10: =-(fin_model!J15/fin_model!J16) -> #DIV/0! | I10: =-(fin_model!K15/fin_model!K16) -> #DIV/0! | ... L10: =-(fin_model!N15/fin_model!N16) -> #DIV/0!
B11: Leverage
A12: Debt to assets ratio | B12: =SUM(fin_model!D41,fin_model!D42,fin_model!D45)/fin_model!D37 -> #DIV/0! | C12: =SUM(fin_model!E41,fin_model!E42,fin_model!E45)/fin_model!E37 -> #DIV/0! | D12: =SUM(fin_model!F41,fin_model!F42,fin_model!F45)/fin_model!F37 -> #DIV/0! | E12: =SUM(fin_model!G41,fin_model!G42,fin_model!G45)/fin_model!G37 -> #DIV/0! | F12: =SUM(fin_model!H41,fin_model!H42,fin_model!H45)/fin_model!H37 -> #DIV/0! | G12: =SUM(fin_model!I41,fin_model!I42,fin_model!I45)/fin_model!I37 -> #DIV/0! | H12: =SUM(fin_model!J41,fin_model!J42,fin_model!J45)/fin_model!J37 -> #DIV/0! | I12: =SUM(fin_model!K41,fin_model!K42,fin_model!K45)/fin_model!K37 -> #DIV/0! | ... L12: =SUM(fin_model!N41,fin_model!N42,fin_model!N45)/fin_model!N37 -> #DIV/0!
A13: Debt to Equity Ratio | B13: =SUM(fin_model!D41,fin_model!D42,fin_model!D45)/fin_model!D51 -> #DIV/0! | C13: =SUM(fin_model!E41,fin_model!E42,fin_model!E45)/fin_model!E51 -> #DIV/0! | D13: =SUM(fin_model!F41,fin_model!F42,fin_model!F45)/fin_model!F51 -> #DIV/0! | E13: =SUM(fin_model!G41,fin_model!G42,fin_model!G45)/fin_model!G51 -> #DIV/0! | F13: =SUM(fin_model!H41,fin_model!H42,fin_model!H45)/fin_model!H51 -> #DIV/0! | G13: =SUM(fin_model!I41,fin_model!I42,fin_model!I45)/fin_model!I51 -> #DIV/0! | H13: =SUM(fin_model!J41,fin_model!J42,fin_model!J45)/fin_model!J51 -> #DIV/0! | I13: =SUM(fin_model!K41,fin_model!K42,fin_model!K45)/fin_model!K51 -> #DIV/0! | ... L13: =SUM(fin_model!N41,fin_model!N42,fin_model!N45)/fin_model!N51 -> #DIV/0!
B14: Efficiency
A15: Asset turnover | B15: =fin_model!D11/fin_model!D37 -> #DIV/0! | C15: =fin_model!E11/fin_model!E37 -> #DIV/0! | D15: =fin_model!F11/fin_model!F37 -> #DIV/0! | E15: =fin_model!G11/fin_model!G37 -> #DIV/0! | F15: =fin_model!H11/fin_model!H37 -> #DIV/0! | G15: =fin_model!I11/fin_model!I37 -> #DIV/0! | H15: =fin_model!J11/fin_model!J37 -> #DIV/0! | I15: =fin_model!K11/fin_model!K37 -> #DIV/0! | ... L15: =fin_model!N11/fin_model!N37 -> #DIV/0!
A16: Receivables days | B16: =(365/(fin_model!D11/fin_model!D30)) -> #DIV/0! | C16: =(365/(fin_model!E11/fin_model!E30)) -> #DIV/0! | D16: =(365/(fin_model!F11/fin_model!F30)) -> #DIV/0! | E16: =(365/(fin_model!G11/fin_model!G30)) -> #DIV/0! | F16: =(365/(fin_model!H11/fin_model!H30)) -> #DIV/0! | G16: =(365/(fin_model!I11/fin_model!I30)) -> #DIV/0! | H16: =(365/(fin_model!J11/fin_model!J30)) -> #DIV/0! | I16: =(365/(fin_model!K11/fin_model!K30)) -> #DIV/0! | ... L16: =(365/(fin_model!N11/fin_model!N30)) -> #DIV/0!
A17: Payables days | B17: =-365/(fin_model!D12/fin_model!D40) -> #DIV/0! | C17: =-365/(fin_model!E12/fin_model!E40) -> #DIV/0! | D17: =-365/(fin_model!F12/fin_model!F40) -> #DIV/0! | E17: =-365/(fin_model!G12/fin_model!G40) -> #DIV/0! | F17: =-365/(fin_model!H12/fin_model!H40) -> #DIV/0! | G17: =-365/(fin_model!I12/fin_model!I40) -> #DIV/0! | H17: =-365/(fin_model!J12/fin_model!J40) -> #DIV/0! | I17: =-365/(fin_model!K12/fin_model!K40) -> #DIV/0! | ... L17: =-365/(fin_model!N12/fin_model!N40) -> #DIV/0!
B18: Profitability
A19: Gross Margin | B19: =(fin_model!D13/fin_model!D11) -> #DIV/0! | C19: =(fin_model!E13/fin_model!E11) -> #DIV/0! | D19: =(fin_model!F13/fin_model!F11) -> #DIV/0! | E19: =(fin_model!G13/fin_model!G11) -> #DIV/0! | F19: =(fin_model!H13/fin_model!H11) -> #DIV/0! | G19: =(fin_model!I13/fin_model!I11) -> #DIV/0! | H19: =(fin_model!J13/fin_model!J11) -> #DIV/0! | I19: =(fin_model!K13/fin_model!K11) -> #DIV/0! | ... L19: =(fin_model!N13/fin_model!N11) -> #DIV/0!
A20: Operating profit margin | B20: =fin_model!D15/fin_model!D11 -> #DIV/0! | C20: =fin_model!E15/fin_model!E11 -> #DIV/0! | D20: =fin_model!F15/fin_model!F11 -> #DIV/0! | E20: =fin_model!G15/fin_model!G11 -> #DIV/0! | F20: =fin_model!H15/fin_model!H11 -> #DIV/0! | G20: =fin_model!I15/fin_model!I11 -> #DIV/0! | H20: =fin_model!J15/fin_model!J11 -> #DIV/0! | I20: =fin_model!K15/fin_model!K11 -> #DIV/0! | ... L20: =fin_model!N15/fin_model!N11 -> #DIV/0!
A21: Net profit margin | B21: =fin_model!D23/fin_model!D11 -> #DIV/0! | C21: =fin_model!E23/fin_model!E11 -> #DIV/0! | D21: =fin_model!F23/fin_model!F11 -> #DIV/0! | E21: =fin_model!G23/fin_model!G11 -> #DIV/0! | F21: =fin_model!H23/fin_model!H11 -> #DIV/0! | G21: =fin_model!I23/fin_model!I11 -> #DIV/0! | H21: =fin_model!J23/fin_model!J11 -> #DIV/0! | I21: =fin_model!K23/fin_model!K11 -> #DIV/0! | ... L21: =fin_model!N23/fin_model!N11 -> #DIV/0!
A22: Return on assets | B22: =fin_model!D23/fin_model!D37 -> #DIV/0! | C22: =((fin_model!E23+fin_model!F23)/2)/fin_model!E37 -> #DIV/0! | D22: =((fin_model!F23+fin_model!G23)/2)/fin_model!F37 -> #DIV/0! | E22: =((fin_model!G23+fin_model!H23)/2)/fin_model!G37 -> #DIV/0! | F22: =((fin_model!H23+fin_model!I23)/2)/fin_model!H37 -> #DIV/0! | G22: =((fin_model!I23+fin_model!H23)/2)/fin_model!I37 -> #DIV/0! | H22: =((fin_model!J23+fin_model!I23)/2)/fin_model!J37 -> #DIV/0! | I22: =((fin_model!K23+fin_model!J23)/2)/fin_model!K37 -> #DIV/0! | J22: =((fin_model!L23+fin_model!K23)/2)/fin_model!L37 -> #DIV/0! | K22: =((fin_model!M23+fin_model!L23)/2)/fin_model!M37 -> #DIV/0! | L22: =((fin_model!N23+fin_model!M23)/2)/fin_model!N37 -> #DIV/0!
A23: Return on invested capital based on a 22.5% tax rate | B23: =(fin_model!D15*(1-0.225))/SUM(fin_model!D41,fin_model!D42,fin_model!D45,fin_model!D51) -> #DIV/0! | C23: =(fin_model!E15*(1-0.225))/SUM(fin_model!E41,fin_model!E42,fin_model!E45,fin_model!E51) -> #DIV/0! | D23: =(fin_model!F15*(1-0.225))/SUM(fin_model!F41,fin_model!F42,fin_model!F45,fin_model!F51) -> #DIV/0! | E23: =(fin_model!G15*(1-0.225))/SUM(fin_model!G41,fin_model!G42,fin_model!G45,fin_model!G51) -> #DIV/0! | F23: =(fin_model!H15*(1-0.225))/SUM(fin_model!H41,fin_model!H42,fin_model!H45,fin_model!H51) -> #DIV/0! | G23: =(fin_model!I15*(1-0.225))/SUM(fin_model!I41,fin_model!I42,fin_model!I45,fin_model!I51) -> #DIV/0! | H23: =(fin_model!J15*(1-0.225))/SUM(fin_model!J41,fin_model!J42,fin_model!J45,fin_model!J51) -> #DIV/0! | I23: =(fin_model!K15*(1-0.225))/SUM(fin_model!K41,fin_model!K42,fin_model!K45,fin_model!K51) -> #DIV/0! | ... L23: =(fin_model!N15*(1-0.225))/SUM(fin_model!N41,fin_model!N42,fin_model!N45,fin_model!N51) -> #DIV/0!
A26: Working capital funding gap | B26: =IFERROR(B28+B16-B17,"N/A") -> N/A | C26: =IFERROR(C28+C16-C17,"N/A") -> N/A | D26: =IFERROR(D28+D16-D17,"N/A") -> N/A | E26: =IFERROR(E28+E16-E17,"N/A") -> N/A | F26: =IFERROR(F28+F16-F17,"N/A") -> N/A | G26: =IFERROR(G28+G16-G17,"N/A") -> N/A | H26: =IFERROR(H28+H16-H17,"N/A") -> N/A | I26: =IFERROR(I28+I16-I17,"N/A") -> N/A | ... L26: =IFERROR(L28+L16-L17,"N/A") -> N/A
A28: Inventory days | B28: =IFERROR(-365/(fin_model!D12/fin_model!D31), "No Inventory") -> No Inventory | C28: =IFERROR(-365/(fin_model!E12/fin_model!E31), "No Inventory") -> No Inventory | D28: =IFERROR(-365/(fin_model!F12/fin_model!F31), "No Inventory") -> No Inventory | E28: =IFERROR(-365/(fin_model!G12/fin_model!G31), "No Inventory") -> No Inventory | F28: =IFERROR(-365/(fin_model!H12/fin_model!H31), "No Inventory") -> No Inventory | G28: =IFERROR(-365/(fin_model!I12/fin_model!I31), "No Inventory") -> No Inventory | H28: =IFERROR(-365/(fin_model!J12/fin_model!J31), "No Inventory") -> No Inventory | I28: =IFERROR(-365/(fin_model!K12/fin_model!K31), "No Inventory") -> No Inventory | ... L28: =IFERROR(-365/(fin_model!N12/fin_model!N31), "No Inventory") -> No Inventory
S34: Historic Period | W34: =G4 -> Forecast period
S35: =C5 -> 2021 | T35: =D5 -> 2022 | U35: =E5 -> 2023 | V35: =F5 -> 2024 | W35: =G5 -> 2025 | X35: =H5 -> 2026 | Y35: =I5 -> 2027 | Z35: =J5 -> 2028 | ... AB35: =L5 -> 2030
S36: Profitability
R37: =A19 -> Gross Margin | S37: =C19 -> #DIV/0! | T37: =D19 -> #DIV/0! | U37: =E19 -> #DIV/0! | V37: =F19 -> #DIV/0! | W37: =G19 -> #DIV/0! | X37: =H19 -> #DIV/0! | Y37: =I19 -> #DIV/0! | Z37: =J19 -> #DIV/0! | ... AB37: =L19 -> #DIV/0!
R38: =A20 -> Operating profit margin | S38: =C20 -> #DIV/0! | T38: =D20 -> #DIV/0! | U38: =E20 -> #DIV/0! | V38: =F20 -> #DIV/0! | W38: =G20 -> #DIV/0! | X38: =H20 -> #DIV/0! | Y38: =I20 -> #DIV/0! | Z38: =J20 -> #DIV/0! | ... AB38: =L20 -> #DIV/0!
R39: =A21 -> Net profit margin | S39: =C21 -> #DIV/0! | T39: =D21 -> #DIV/0! | U39: =E21 -> #DIV/0! | V39: =F21 -> #DIV/0! | W39: =G21 -> #DIV/0! | X39: =H21 -> #DIV/0! | Y39: =I21 -> #DIV/0! | Z39: =J21 -> #DIV/0! | ... AB39: =L21 -> #DIV/0!
S40: Liquidity
R41: =A7 -> Current ratio | S41: =C7 -> #DIV/0! | T41: =D7 -> #DIV/0! | U41: =E7 -> #DIV/0! | V41: =F7 -> #DIV/0! | W41: =G7 -> #DIV/0! | X41: =H7 -> #DIV/0! | Y41: =I7 -> #DIV/0! | Z41: =J7 -> #DIV/0! | ... AB41: =L7 -> #DIV/0!
R42: =A8 -> Quick ratio | S42: =C8 -> #DIV/0! | T42: =D8 -> #DIV/0! | U42: =E8 -> #DIV/0! | V42: =F8 -> #DIV/0! | W42: =G8 -> #DIV/0! | X42: =H8 -> #DIV/0! | Y42: =I8 -> #DIV/0! | Z42: =J8 -> #DIV/0! | ... AB42: =L8 -> #DIV/0!
S43: Leverage
R44: =A12 -> Debt to assets ratio | S44: =C12 -> #DIV/0! | T44: =D12 -> #DIV/0! | U44: =E12 -> #DIV/0! | V44: =F12 -> #DIV/0! | W44: =G12 -> #DIV/0! | X44: =H12 -> #DIV/0! | Y44: =I12 -> #DIV/0! | Z44: =J12 -> #DIV/0! | ... AB44: =L12 -> #DIV/0!
R45: Debt to Equity Ratio | S45: =C13 -> #DIV/0! | T45: =D13 -> #DIV/0! | U45: =E13 -> #DIV/0! | V45: =F13 -> #DIV/0! | W45: =G13 -> #DIV/0! | X45: =H13 -> #DIV/0! | Y45: =I13 -> #DIV/0! | Z45: =J13 -> #DIV/0! | ... AB45: =L13 -> #DIV/0!

Sheet mergent_raw
A4: Powered by Clearbit
A5: Franklin Resources Inc (NYS: BEN)
A8: General Company Information
A9: Principal Office | B9: Website
A10: One Franklin Parkway San Mateo, CA 94403 USA | B10: www.franklinresources.com
A12: Phone | B12: Primary NAICS
A13: 650 312-2000 | B13: 523940 : Portfolio Management and Investment Advice
A15: Fax | B15: Closing Stock Price
A16: 650 312-3655 | B16: 20.11 (as of 12/30/2024)
A18: Number of Employees | B18: Incorporated
A19: 9,200 (Approximate Full-Time as of 09/30/2023) | B19: December 1969 , DE, United States
A21: Country | B21: Mergent Dividend Achiever
A22: United States | B22: Yes, # of Years: 34
A24: Exchange and Ticker | B24: Number of Shareholders
A25: NYS : BEN | B25: 2,476 (record) (as of 10/31/2023)
A27: Primary SIC
A28: 6282 : Investment advice
A31: Business Summary
A32: Franklin Resources, Inc. is a global investment management company with subsidiaries operating as Franklin Templeton and serving clients in over 150 countries. It offers specialization on a global scale, bringing capabilities in fixed income, equity,
A33: alternatives and multi-asset solutions. Co. provides its investment management and related services to retail, institutional and high-net-worth investors in jurisdictions worldwide. Its investment products include sponsored funds, as well as
A34: institutional and high-net-worth separate accounts, retail separately managed account programs, sub-advised products, and other investment vehicles.
A36: * all results are stated in US Dollars
A38: Peer Grouping by: | B38: SIC
A39: Peer Scope: | B39: worldwide
A41: Company Name | B41: Current Ratio - latest | D41: Quick Ratio - latest | F41: Total Debt to Equity - latest | H41: Inventory Turnover - latest | J41: Operating Margin % - latest | L41: ROA % (Net) - latest | N41: ROI % (Operating) - latest | P41: ROE % (Net) - latest | R41: Total Asset Turnover - latest | T41: Net Profit Margin % - latest | V41: Interest Coverage - latest

Sheet mergent_work
A2: Target Country (United States)
A3: Peer Grouping by: | B3: SIC
A4: Peer Scope: | B4: country
A6: Company Name | B6: Current Ratio - latest | D6: Quick Ratio - latest | F6: Total Debt to Equity - latest | H6: Inventory Turnover - latest | J6: Operating Margin % - latest | L6: ROA % (Net) - latest | N6: ROI % (Operating) - latest | P6: ROE % (Net) - latest | R6: Total Asset Turnover - latest | T6: Net Profit Margin % - latest | V6: Interest Coverage - latest
A20: 25th percentile | B20: =_xlfn.PERCENTILE.INC(B7:B15,0.25) -> #NUM! | D20: =_xlfn.PERCENTILE.INC(D7:D15,0.25) -> #NUM! | F20: =_xlfn.PERCENTILE.INC(F7:F15,0.25) -> #NUM! | H20: =_xlfn.PERCENTILE.INC(H7:H15,0.25) -> #NUM! | J20: =_xlfn.PERCENTILE.INC(J7:J15,0.25) -> #NUM! | L20: =_xlfn.PERCENTILE.INC(L7:L15,0.25) -> #NUM! | N20: =_xlfn.PERCENTILE.INC(N7:N15,0.25) -> #NUM! | P20: =_xlfn.PERCENTILE.INC(P7:P15,0.25) -> #NUM! | R20: =_xlfn.PERCENTILE.INC(R7:R15,0.25) -> #NUM! | T20: =_xlfn.PERCENTILE.INC(T7:T15,0.25) -> #NUM! | V20: =_xlfn.PERCENTILE.INC(V7:V15,0.25) -> #NUM!
A21: Median | B21: =MEDIAN(B7:B15) -> #NUM! | D21: =MEDIAN(D7:D15) -> #NUM! | F21: =MEDIAN(F7:F15) -> #NUM! | H21: =MEDIAN(H7:H15) -> #NUM! | J21: =MEDIAN(J7:J15) -> #NUM! | L21: =MEDIAN(L7:L15) -> #NUM! | N21: =MEDIAN(N7:N15) -> #NUM! | P21: =MEDIAN(P7:P15) -> #NUM! | R21: =MEDIAN(R7:R15) -> #NUM! | T21: =MEDIAN(T7:T15) -> #NUM! | V21: =MEDIAN(V7:V15) -> #NUM!
A22: Mean | B22: =AVERAGE(B7:B15) -> #DIV/0! | D22: =AVERAGE(D7:D15) -> #DIV/0! | F22: =AVERAGE(F7:F15) -> #DIV/0! | H22: =AVERAGE(H7:H15) -> #DIV/0! | J22: =AVERAGE(J7:J15) -> #DIV/0! | L22: =AVERAGE(L7:L15) -> #DIV/0! | N22: =AVERAGE(N7:N15) -> #DIV/0! | P22: =AVERAGE(P7:P15) -> #DIV/0! | R22: =AVERAGE(R7:R15) -> #DIV/0! | T22: =AVERAGE(T7:T15) -> #DIV/0! | V22: =AVERAGE(V7:V15) -> #DIV/0!
A23: 75th percentile | B23: =_xlfn.PERCENTILE.INC(B7:B15,0.75) -> #NUM! | D23: =_xlfn.PERCENTILE.INC(D7:D15,0.75) -> #NUM! | F23: =_xlfn.PERCENTILE.INC(F7:F15,0.75) -> #NUM! | H23: =_xlfn.PERCENTILE.INC(H7:H15,0.75) -> #NUM! | J23: =_xlfn.PERCENTILE.INC(J7:J15,0.75) -> #NUM! | L23: =_xlfn.PERCENTILE.INC(L7:L15,0.75) -> #NUM! | N23: =_xlfn.PERCENTILE.INC(N7:N15,0.75) -> #NUM! | P23: =_xlfn.PERCENTILE.INC(P7:P15,0.75) -> #NUM! | R23: =_xlfn.PERCENTILE.INC(R7:R15,0.75) -> #NUM! | T23: =_xlfn.PERCENTILE.INC(T7:T15,0.75) -> #NUM! | V23: =_xlfn.PERCENTILE.INC(V7:V15,0.75) -> #NUM!

Sheet mergent_report
C1: Financial statement analysis for firm: comparison with peers, most recent data
A2: Mergent variable | B2: Our variable | C2: My company | D2: Peer median
A3: Current Ratio - latest | B3: Current ratio | C3: =mergent_work!B18 -> 0 | D3: =mergent_work!B21 -> #NUM!
A4: Quick Ratio - latest | B4: Quick ratio | C4: =mergent_work!D18 -> 0 | D4: =mergent_work!D21 -> #NUM!
A5: Interest Coverage - latest | B5: Times interest earned (from EBIT) | C5: =mergent_work!V18 -> 0 | D5: =mergent_work!V21 -> #NUM!
A6: Total Debt to Equity - latest | B6: Debt-to-equity | C6: =mergent_work!F18 -> 0 | D6: =mergent_work!F21 -> #NUM!
A7: Inventory Turnover - latest | B7: Inventory turnover | C7: =mergent_work!H18 -> 0 | D7: =mergent_work!H21 -> #NUM!
A8: Total Asset Turnover - latest | B8: Asset turnover | C8: =mergent_work!R18 -> 0 | D8: =mergent_work!R21 -> #NUM!
A9: Operating Margin % - latest | B9: Operating profit margin | C9: =mergent_work!J18 -> 0 | D9: =mergent_work!J21 -> #NUM!
A10: Net Profit Margin % - latest | B10: Net profit margin | C10: =mergent_work!T18 -> 0 | D10: =mergent_work!T21 -> #NUM!
A11: ROA % (Net) - latest | B11: Return on assets | C11: =mergent_work!L18 -> 0 | D11: =mergent_work!L21 -> #NUM!
A12: ROI % (Operating) - latest | B12: Return on invested capital | C12: =mergent_work!N18 -> 0 | D12: =mergent_work!N21 -> #NUM!

Sheet WACC
A1: Market value of equity | E1: If the interest coverage ratio (based on EBIT) is
A2: Weighted average basic shares outstanding (in millions, end of historical period) | B2: =fin_model!H54 -> 0 | E2: Greater than | F2: And equal to or less than | G2: Then rating is | H2: And spread is
A3: Price (as of valuation date) | B3: =fin_model!C5 -> 0 | E3: 8.5 | F3: Infinity | G3: Aaa / AAA | H3: 0.0059
A4: Market value of equity ($ millions) | B4: =WACC!B2*WACC!B3 -> 0 | E4: 6.5 | F4: 8.5 | G4: Aa2 / AA | H4: 0.007
E5: 5.5 | F5: 6.5 | G5: A1 / A+ | H5: 0.0092
A6: Market value of debt | E6: 4.25 | F6: 5.5 | G6: A2 / A | H6: 0.0107
A7: Short-term debt (at end of historical period) | B7: =fin_model!H41 -> 0 | E7: 3 | F7: 4.25 | G7: A3 / A- | H7: 0.0121
A8: Current portion of long-term debt (at end of historical period) | B8: =fin_model!H42 -> 0 | E8: 2.5 | F8: 3 | G8: Baa2 / BBB | H8: 0.0147
A9: Long-term debt in long-term liabilities (at end of historical period) | B9: =fin_model!H45 -> 0 | E9: 2.25 | F9: 2.5 | G9: Ba1 / BB+ | H9: 0.0174
A10: Market value of debt ($ millions) | B10: =SUM(B7:B9) -> 0 | E10: 2 | F10: 2.25 | G10: Ba2 / BB | H10: 0.0221
E11: 1.75 | F11: 2 | G11: B1 / B+ | H11: 0.0314
A12: Market value of debt & equity | E12: 1.5 | F12: 1.75 | G12: B2 / B | H12: 0.0361
A13: Market value of debt & equity ($ millions) | B13: =B4+B10 -> 0 | E13: 1.25 | F13: 1.5 | G13: B3 / B- | H13: 0.0524
E14: 0.8 | F14: 1.25 | G14: Caa / CCC | H14: 0.0851
A15: Weights | E15: 0.65 | F15: 0.8 | G15: Ca2 / CC | H15: 0.1178
A16: Equity weight | B16: =B4/B13 -> #DIV/0! | E16: 0.2 | F16: 0.65 | G16: C2 / C | H16: 0.17
A17: Debt weight | B17: =B10/B13 -> #DIV/0! | E17: Negative infinity | F17: 0.2 | G17: D2 / D | H17: 0.2
E18: Source of table
A19: Tax rate
A20: Tax rate (rounded to 2 decimal places) | B20: 0.225 | C20: Average tax rate from 2019 - 2022
P21: Value of debt may be different from balance sheet to represent difference between carrying value and fair value
A22: Expected return of debt
A23: EBIT in last year of historical period | B23: =fin_model!H19-fin_model!H16 -> 0
A24: Interest expense from debt in last year of historical period (as positive) | B24: =-fin_model!H16 -> 0 | R24: Sums of weighted interest and $ amount | S24: =SUM(S27:S65) -> 2788.9 | T24: =SUM(T27:T65) -> 69.98532
A25: Times interest earned = EBIT/interest | B25: =B23/B24 -> #DIV/0! | R25: Weighted int / $ amount | S25: =(T24/S24) -> 0.025094238
A26: Spread (according to times interest earned, external rating, or analyst judgement) | B26: 0.0059 | P26: Year debt is due | R26: Interest rate | S26: $ amount owed | T26: Weighted Interest
A27: Risk-free rate | B27: 0.0457 | C27: 10 year treasury bond return (10 year is standard per Corporate finance Investment and Advisory Application) | P27: 2024 | T27: =R27*S27 -> 0
A28: Expected return of firm's debt (not rounded) | B28: =B27+B26 -> 0.0516 | C28: if company is private B29 = B28, if company is public B29 = C29 | P28: =P27+1 -> 2025 | R28: 0.0297 | S28: 400 | T28: =R28*S28 -> 11.88
A29: Expected return of firm's debt (rounded) | B29: =ROUND(C29,4) -> 0.0251 | C29: =S25 -> 0.025094238 | P29: =P28+1 -> 2026 | R29: 0.018 | S29: 469.5 | T29: =R29*S29 -> 8.451
D30: 2nd method return on debt | P30: =P29+1 -> 2027 | T30: =R30*S30 -> 0
A31: Expected return of equity = RF + (β × market premium) | P31: =P30+1 -> 2028 | T31: =R31*S31 -> 0
A32: Risk-free rate | B32: =B27 -> 0.0457 | P32: =P31+1 -> 2029 | T32: =R32*S32 -> 0
A33: Beta | B33: 1.57 | C33: (3 year monthly) | P33: =P32+1 -> 2030 | R33: 0.0174 | S33: 847.5 | T33: =R33*S33 -> 14.7465
A34: Market premium | B34: 0.05 | C34: Kroll | P34: =P33+1 -> 2031 | T34: =R34*S34 -> 0
A35: Expected return of firm's equity (not rounded) | B35: =B32+(B33*B34) -> 0.1242 | P35: =P34+1 -> 2032 | T35: =R35*S35 -> 0
A36: Expected return of firm's equity (rounded) | B36: =ROUND(B35,4) -> 0.1242 | P36: =P35+1 -> 2033 | T36: =R36*S36 -> 0
P37: =P36+1 -> 2034 | T37: =R37*S37 -> 0
A38: WACC = [(E/V) × RE] + [(D/V) × (1 – Tc) × RD] | P38: =P37+1 -> 2035 | T38: =R38*S38 -> 0
A39: Equity weight | B39: =B16 -> #DIV/0! | P39: =P38+1 -> 2036 | T39: =R39*S39 -> 0
A40: Expected return of firm's equity (rounded) | B40: =B36 -> 0.1242 | P40: =P39+1 -> 2037 | T40: =R40*S40 -> 0
...

Sheet DCF_-_FCFF_341
B1: DCF Analysis | C1: Forecast yr 1 | D1: Forecast yr 2 | E1: Forecast yr 3 | F1: Forecast yr 4 | G1: Forecast yr 5 | H1: Forecast yr 6 | I1: Terminal
B2: FCFF & Terminal Value
B3: EBIT × (1 - tax rate) | C3: =(fin_model!I19-fin_model!I16)*(1-WACC!$B20) -> #DIV/0! | D3: =(fin_model!J19-fin_model!J16)*(1-WACC!$B20) -> #DIV/0! | E3: =(fin_model!K19-fin_model!K16)*(1-WACC!$B20) -> #DIV/0! | F3: =(fin_model!L19-fin_model!L16)*(1-WACC!$B20) -> #DIV/0! | G3: =(fin_model!M19-fin_model!M16)*(1-WACC!$B20) -> #DIV/0! | H3: =(fin_model!N19-fin_model!N16)*(1-WACC!$B20) -> #DIV/0!
B4: Depreciation | C4: =fin_model!I60 -> #DIV/0! | D4: =fin_model!J60 -> #DIV/0! | E4: =fin_model!K60 -> #DIV/0! | F4: =fin_model!L60 -> #DIV/0! | G4: =fin_model!M60 -> #DIV/0! | H4: =fin_model!N60 -> #DIV/0!
B5: Amortization | C5: =fin_model!I61 -> #DIV/0! | D5: =fin_model!J61 -> #DIV/0! | E5: =fin_model!K61 -> #DIV/0! | F5: =fin_model!L61 -> #DIV/0! | G5: =fin_model!M61 -> #DIV/0! | H5: =fin_model!N61 -> #DIV/0!
B6: Other cash flow from operating activities | C6: =fin_model!I62 -> #DIV/0! | D6: =fin_model!J62 -> #DIV/0! | E6: =fin_model!K62 -> #DIV/0! | F6: =fin_model!L62 -> #DIV/0! | G6: =fin_model!M62 -> #DIV/0! | H6: =fin_model!N62 -> #DIV/0!
B7: Capital expenditures (CAPEX) | C7: =fin_model!I66 -> #DIV/0! | D7: =fin_model!J66 -> #DIV/0! | E7: =fin_model!K66 -> #DIV/0! | F7: =fin_model!L66 -> #DIV/0! | G7: =fin_model!M66 -> #DIV/0! | H7: =fin_model!N66 -> #DIV/0!
B8: FCFF | C8: =SUM(C3:C7) -> #DIV/0! | D8: =SUM(D3:D7) -> #DIV/0! | E8: =SUM(E3:E7) -> #DIV/0! | F8: =SUM(F3:F7) -> #DIV/0! | G8: =SUM(G3:G7) -> #DIV/0! | H8: =SUM(H3:H7) -> #DIV/0!
B9: Terminal value (as a perpetuity) | I9: =D53 -> #DIV/0!
B10: Terminal value (from a multiple) | I10: =C61 -> #DIV/0!
B12: Terminal value (as a perpetuity)
B13: Years to discount | C13: 1 | D13: 2 | E13: 3 | F13: 4 | G13: 5 | H13: 6 | I13: 6
B14: Present values with terminal value as a perpetuity | C14: =C8/(1+$C$22)^(C13) -> #DIV/0! | D14: =D8/(1+$C$22)^D13 -> #DIV/0! | E14: =E8/(1+$C$22)^E13 -> #DIV/0! | F14: =F8/(1+$C$22)^F13 -> #DIV/0! | G14: =G8/(1+$C$22)^G13 -> #DIV/0! | H14: =H8/(1+$C$22)^H13 -> #DIV/0! | I14: =I9/(1+C22)^I13 -> #DIV/0!
B16: Terminal value (from a multiple)
B17: Years to discount | C17: 1 | D17: 2 | E17: 3 | F17: 4 | G17: 5 | H17: 6 | I17: 6
B18: Present values with terminal value from a multiple | C18: =C8/(1+$C$22)^(C13) -> #DIV/0! | D18: =D8/(1+$C$22)^D13 -> #DIV/0! | E18: =E8/(1+$C$22)^E13 -> #DIV/0! | F18: =F8/(1+$C$22)^F13 -> #DIV/0! | G18: =G8/(1+$C$22)^G13 -> #DIV/0! | H18: =H8/(1+$C$22)^H13 -> #DIV/0! | I18: =I10/(1+C22)^I17 -> #DIV/0!
B20: Valuation Analysis
B21: Terminal growth rate | C21: 0.01
B22: WACC | C22: =WACC!B45 -> #DIV/0!
B23: Expected return of equity | C23: =WACC!B36 -> 0.1242
B24: Terminal EV/EBITDA | C24: 8 | E24: Sourced from Damodaran | F24: If no data from damodaran use equidam
B26: Date of end of historical period | C26: =fin_model!C7 -> 0
B27: Valuation date | C27: =fin_model!C6 -> 0
B29: Terminal value (as a perpetuity)
B30: Estimated enterprise value (at end of historical period) | C30: =SUM(C14:I14) -> #DIV/0!
B31: Value of net debt (at end of historical period) | C31: =C67 -> 0
B32: Estimated equity value (at end of historical period) | C32: =C30-C31 -> #DIV/0!
B33: Weighted average basic shares outstanding (in millions, end of historical period) | C33: =fin_model!H54 -> 0
B34: Estimated price per share (at end of historical period) | C34: =C32/C33 -> #DIV/0!
B35: Share of year between end of historical period & valuation date | C35: =YEARFRAC(C27,C26) -> 0
B36: Estimated price per share (at valuation date) | C36: =C34*(1+C23)^C35 -> #DIV/0!
B38: Terminal value (from a multiple)
B39: Estimated enterprise value (at end of historical period) | C39: =SUM(C18:I18) -> #DIV/0!
B40: Value of net debt (at end of historical period) | C40: =C31 -> 0
B41: Estimated equity value (at end of historical period) | C41: =C39-C40 -> #DIV/0!
B42: Weighted average basic shares outstanding (in millions, end of historical period) | C42: =C33 -> 0
B43: Estimated price per share (at end of historical period) | C43: =C41/C42 -> #DIV/0!
B44: Share of year between end of historical period & valuation date | C44: =C35 -> 0
B45: Estimated price per share (at valuation date) | C45: =C43*(1+C23)^C44 -> #DIV/0!
C48: Forecast yr 6
...

Sheet DCF_-_FCFF_timing
B1: DCF Analysis | C1: Forecast yr 1 | D1: Forecast yr 2 | E1: Forecast yr 3 | F1: Forecast yr 4 | G1: Forecast yr 5 | H1: Forecast yr 6 | I1: Terminal
B2: FCFF & Terminal Value
B3: EBIT × (1 - tax rate) | C3: ='DCF_-_FCFF_341'!C3 -> #DIV/0! | D3: ='DCF_-_FCFF_341'!D3 -> #DIV/0! | E3: ='DCF_-_FCFF_341'!E3 -> #DIV/0! | F3: ='DCF_-_FCFF_341'!F3 -> #DIV/0! | G3: ='DCF_-_FCFF_341'!G3 -> #DIV/0! | H3: ='DCF_-_FCFF_341'!H3 -> #DIV/0!
B4: Depreciation | C4: ='DCF_-_FCFF_341'!C4 -> #DIV/0! | D4: ='DCF_-_FCFF_341'!D4 -> #DIV/0! | E4: ='DCF_-_FCFF_341'!E4 -> #DIV/0! | F4: ='DCF_-_FCFF_341'!F4 -> #DIV/0! | G4: ='DCF_-_FCFF_341'!G4 -> #DIV/0! | H4: ='DCF_-_FCFF_341'!H4 -> #DIV/0!
B5: Amortization | C5: ='DCF_-_FCFF_341'!C5 -> #DIV/0! | D5: ='DCF_-_FCFF_341'!D5 -> #DIV/0! | E5: ='DCF_-_FCFF_341'!E5 -> #DIV/0! | F5: ='DCF_-_FCFF_341'!F5 -> #DIV/0! | G5: ='DCF_-_FCFF_341'!G5 -> #DIV/0! | H5: ='DCF_-_FCFF_341'!H5 -> #DIV/0!
B6: Other cash flow from operating activities | C6: ='DCF_-_FCFF_341'!C6 -> #DIV/0! | D6: ='DCF_-_FCFF_341'!D6 -> #DIV/0! | E6: ='DCF_-_FCFF_341'!E6 -> #DIV/0! | F6: ='DCF_-_FCFF_341'!F6 -> #DIV/0! | G6: ='DCF_-_FCFF_341'!G6 -> #DIV/0! | H6: ='DCF_-_FCFF_341'!H6 -> #DIV/0!
B7: Capital expenditures (CAPEX) | C7: ='DCF_-_FCFF_341'!C7 -> #DIV/0! | D7: ='DCF_-_FCFF_341'!D7 -> #DIV/0! | E7: ='DCF_-_FCFF_341'!E7 -> #DIV/0! | F7: ='DCF_-_FCFF_341'!F7 -> #DIV/0! | G7: ='DCF_-_FCFF_341'!G7 -> #DIV/0! | H7: ='DCF_-_FCFF_341'!H7 -> #DIV/0!
B8: FCFF | C8: =SUM(C3:C7) -> #DIV/0! | D8: =SUM(D3:D7) -> #DIV/0! | E8: =SUM(E3:E7) -> #DIV/0! | F8: =SUM(F3:F7) -> #DIV/0! | G8: =SUM(G3:G7) -> #DIV/0! | H8: =SUM(H3:H7) -> #DIV/0!
B9: Terminal value (as a perpetuity) | I9: =D55 -> #DIV/0!
B10: Terminal value (from a multiple) | I10: =C63 -> #DIV/0!
B12: Share of year expected for CF or TV | C12: =1-YEARFRAC(fin_model!C7,fin_model!C6) -> 1 | D12: 1 | E12: 1 | F12: 1 | G12: 1 | H12: 1 | I12: 1
B13: Expected FCFF or TV (as a perpetuity) | C13: =C8*C12 -> #DIV/0! | D13: =D8*D12 -> #DIV/0! | E13: =E8*E12 -> #DIV/0! | F13: =F8*F12 -> #DIV/0! | G13: =G8*G12 -> #DIV/0! | H13: =H8*H12 -> #DIV/0! | I13: =I9*I12 -> #DIV/0!
B14: Expected FCFF or TV (from a multiple) | C14: =C8*C12 -> #DIV/0! | D14: =D8*D12 -> #DIV/0! | E14: =E8*E12 -> #DIV/0! | F14: =F8*F12 -> #DIV/0! | G14: =G8*G12 -> #DIV/0! | H14: =H8*H12 -> #DIV/0! | I14: =I10*I12 -> #DIV/0!
B16: Terminal value (as a perpetuity)
B17: Period | C17: 1 | D17: 2 | E17: 3 | F17: 4 | G17: 5 | H17: 6 | I17: 6
B18: Years to discount | C18: =0.5*(1-YEARFRAC(C31,C32)) -> 0.5 | D18: =D17-YEARFRAC($C$31,$C32)-0.5 -> 1.5 | E18: =E17-YEARFRAC($C$31,$C32)-0.5 -> 2.5 | F18: =F17-YEARFRAC($C$31,$C32)-0.5 -> 3.5 | G18: =G17-YEARFRAC($C$31,$C32)-0.5 -> 4.5 | H18: =H17-YEARFRAC($C$31,$C32)-0.5 -> 5.5 | I18: =I17-YEARFRAC($C$31,$C32)-0.5 -> 5.5
B19: Present values with terminal value as a perpetuity | C19: =C13/(1+$C$28)^C18 -> #DIV/0! | D19: =D13/(1+$C$28)^D18 -> #DIV/0! | E19: =E13/(1+$C$28)^E18 -> #DIV/0! | F19: =F13/(1+$C$28)^F18 -> #DIV/0! | G19: =G13/(1+$C$28)^G18 -> #DIV/0! | H19: =H13/(1+$C$28)^H18 -> #DIV/0! | I19: =I13/(1+$C$28)^I18 -> #DIV/0!
B21: Terminal value (from a multiple)
B22: Period | C22: 1 | D22: 2 | E22: 3 | F22: 4 | G22: 5 | H22: 6 | I22: 6
B23: Years to discount | C23: =C18 -> 0.5 | D23: =D18 -> 1.5 | E23: =E18 -> 2.5 | F23: =F18 -> 3.5 | G23: =G18 -> 4.5 | H23: =H18 -> 5.5 | I23: =I17-YEARFRAC($C$31,$C32) -> 6
B24: Present values with terminal value from a multiple | C24: =C14/(1+$C$28)^C18 -> #DIV/0! | D24: =D14/(1+$C$28)^D18 -> #DIV/0! | E24: =E14/(1+$C$28)^E18 -> #DIV/0! | F24: =F14/(1+$C$28)^F18 -> #DIV/0! | G24: =G14/(1+$C$28)^G18 -> #DIV/0! | H24: =H14/(1+$C$28)^H18 -> #DIV/0! | I24: =I14/(1+$C$28)^I23 -> #DIV/0!
B26: Valuation Analysis
B27: Terminal growth rate | C27: ='DCF_-_FCFF_341'!C21 -> 0.01 | J27: What-If Analysis of DCF as a perpetuity
B28: WACC | C28: ='DCF_-_FCFF_341'!C22 -> #DIV/0! | L28: Terminal Growth Rate
B29: Terminal EV/EBITDA | C29: ='DCF_-_FCFF_341'!C24 -> 8 | I29: =C41 -> #DIV/0! | J29: 0.005 | K29: 0.0075 | L29: 0.01 | M29: 0.0125 | N29: 0.015
I30: 0.1025 | J30: #DIV/0! | K30: #DIV/0! | L30: #DIV/0! | M30: #DIV/0! | N30: #DIV/0!
B31: Date of end of historical period | C31: =fin_model!C7 -> 0 | I31: 0.1051 | J31: #DIV/0! | K31: #DIV/0! | L31: #DIV/0! | M31: #DIV/0! | N31: #DIV/0!
B32: Valuation date | C32: ='DCF_-_FCFF_341'!C27 -> 0 | H32: WACC | I32: 0.1076 | J32: #DIV/0! | K32: #DIV/0! | L32: #DIV/0! | M32: #DIV/0! | N32: #DIV/0!
I33: 0.1101 | J33: #DIV/0! | K33: #DIV/0! | L33: #DIV/0! | M33: #DIV/0! | N33: #DIV/0!
I34: 0.1126 | J34: #DIV/0! | K34: #DIV/0! | L34: #DIV/0! | M34: #DIV/0! | N34: #DIV/0!
B36: Terminal value (as a perpetuity) | I36: Price at valuation date | K36: =fin_model!C5 -> 0
B37: Estimated enterprise value (as of valuation date) | C37: =SUM(C19:I19) -> #DIV/0!
B38: Value of net debt (at end of historical period) | C38: ='DCF_-_FCFF_341'!C31 -> 0
B39: Estimated equity value (as of valuation date) | C39: =C37-C38 -> #DIV/0!
B40: Weighted average basic shares outstanding (in millions, end of historical period) | C40: ='DCF_-_FCFF_341'!C33 -> 0
B41: Estimated price per share (as of valuation date) | C41: =C39/C40 -> #DIV/0! | J41: What-If Analysis of DCF as a multiple
L42: Exit Multiple
B43: Terminal value (from a multiple) | I43: =C48 -> #DIV/0! | J43: 8.5 | K43: 9 | L43: 9.5 | M43: 10 | N43: 10.5
B44: Estimated enterprise value (as of valuation date) | C44: =SUM(C24:I24) -> #DIV/0! | I44: 0.1003 | J44: #DIV/0! | K44: #DIV/0! | L44: #DIV/0! | M44: #DIV/0! | N44: #DIV/0!
B45: Value of net debt (at end of historical period) | C45: ='DCF_-_FCFF_341'!C40 -> 0 | I45: 0.1028 | J45: #DIV/0! | K45: #DIV/0! | L45: #DIV/0! | M45: #DIV/0! | N45: #DIV/0!
...

Sheet DCF_-_FCFF_timing_&_normalized
B1: DCF Analysis | C1: Forecast yr 1 | D1: Forecast yr 2 | E1: Forecast yr 3 | F1: Forecast yr 4 | G1: Forecast yr 5 | H1: Forecast yr 6 | I1: Terminal | J1: Normalized yr 6
B2: FCFF & Terminal Value
B3: EBIT × (1 - tax rate) | C3: ='DCF_-_FCFF_341'!C3 -> #DIV/0! | D3: ='DCF_-_FCFF_341'!D3 -> #DIV/0! | E3: ='DCF_-_FCFF_341'!E3 -> #DIV/0! | F3: ='DCF_-_FCFF_341'!F3 -> #DIV/0! | G3: ='DCF_-_FCFF_341'!G3 -> #DIV/0! | H3: ='DCF_-_FCFF_341'!H3 -> #DIV/0! | J3: =E75 -> #DIV/0!
B4: Depreciation | C4: ='DCF_-_FCFF_341'!C4 -> #DIV/0! | D4: ='DCF_-_FCFF_341'!D4 -> #DIV/0! | E4: ='DCF_-_FCFF_341'!E4 -> #DIV/0! | F4: ='DCF_-_FCFF_341'!F4 -> #DIV/0! | G4: ='DCF_-_FCFF_341'!G4 -> #DIV/0! | H4: ='DCF_-_FCFF_341'!H4 -> #DIV/0! | J4: =H4 -> #DIV/0!
B5: Amortization | C5: ='DCF_-_FCFF_341'!C5 -> #DIV/0! | D5: ='DCF_-_FCFF_341'!D5 -> #DIV/0! | E5: ='DCF_-_FCFF_341'!E5 -> #DIV/0! | F5: ='DCF_-_FCFF_341'!F5 -> #DIV/0! | G5: ='DCF_-_FCFF_341'!G5 -> #DIV/0! | H5: ='DCF_-_FCFF_341'!H5 -> #DIV/0! | J5: =H5 -> #DIV/0!
B6: Other cash flow from operating activities | C6: ='DCF_-_FCFF_341'!C6 -> #DIV/0! | D6: ='DCF_-_FCFF_341'!D6 -> #DIV/0! | E6: ='DCF_-_FCFF_341'!E6 -> #DIV/0! | F6: ='DCF_-_FCFF_341'!F6 -> #DIV/0! | G6: ='DCF_-_FCFF_341'!G6 -> #DIV/0! | H6: ='DCF_-_FCFF_341'!H6 -> #DIV/0! | J6: =H6 -> #DIV/0!
B7: Capital expenditures (CAPEX) | C7: ='DCF_-_FCFF_341'!C7 -> #DIV/0! | D7: ='DCF_-_FCFF_341'!D7 -> #DIV/0! | E7: ='DCF_-_FCFF_341'!E7 -> #DIV/0! | F7: ='DCF_-_FCFF_341'!F7 -> #DIV/0! | G7: ='DCF_-_FCFF_341'!G7 -> #DIV/0! | H7: ='DCF_-_FCFF_341'!H7 -> #DIV/0! | J7: =H7 -> #DIV/0!
B8: FCFF | C8: =SUM(C3:C7) -> #DIV/0! | D8: =SUM(D3:D7) -> #DIV/0! | E8: =SUM(E3:E7) -> #DIV/0! | F8: =SUM(F3:F7) -> #DIV/0! | G8: =SUM(G3:G7) -> #DIV/0! | H8: =SUM(H3:H7) -> #DIV/0! | J8: =SUM(J3:J7) -> #DIV/0!
B9: Terminal value (as a perpetuity) | I9: =F82 -> #DIV/0!
B10: Terminal value (from a multiple) | I10: =E90 -> #DIV/0!
B12: Share of year expected for CF or TV | C12: =1-YEARFRAC(C31,C32) -> 1 | D12: 1 | E12: 1 | F12: 1 | G12: 1 | H12: 1 | I12: 1
B13: Expected FCFF or TV (as a perpetuity) | C13: =C8*C12 -> #DIV/0! | D13: =D8*D12 -> #DIV/0! | E13: =E8*E12 -> #DIV/0! | F13: =F8*F12 -> #DIV/0! | G13: =G8*G12 -> #DIV/0! | H13: =H8*H12 -> #DIV/0! | I13: =I9*I12 -> #DIV/0!
B14: Expected FCFF or TV (from a multiple) | C14: =C8*C12 -> #DIV/0! | D14: =D8*D12 -> #DIV/0! | E14: =E8*E12 -> #DIV/0! | F14: =F8*F12 -> #DIV/0! | G14: =G8*G12 -> #DIV/0! | H14: =H8*H12 -> #DIV/0! | I14: =I10*I12 -> #DIV/0!
B16: Terminal value (as a perpetuity)
B17: Period | C17: 1 | D17: 2 | E17: 3 | F17: 4 | G17: 5 | H17: 6 | I17: 6
B18: Years to discount | C18: =0.5*C12 -> 0.5 | D18: =(D17-1)+$C$12-0.5 -> 1.5 | E18: =(E17-1)+$C$12-0.5 -> 2.5 | F18: =(F17-1)+$C$12-0.5 -> 3.5 | G18: =(G17-1)+$C$12-0.5 -> 4.5 | H18: =(H17-1)+$C$12-0.5 -> 5.5 | I18: =(I17-1)+$C$12-0.5 -> 5.5
B19: Present values with terminal value as a perpetuity | C19: =C13/(1+$C$28)^C18 -> #DIV/0! | D19: =D13/(1+$C$28)^D18 -> #DIV/0! | E19: =E13/(1+$C$28)^E18 -> #DIV/0! | F19: =F13/(1+$C$28)^F18 -> #DIV/0! | G19: =G13/(1+$C$28)^G18 -> #DIV/0! | H19: =H13/(1+$C$28)^H18 -> #DIV/0! | I19: =I13/(1+$C$28)^I18 -> #DIV/0!
B21: Terminal value (from a multiple)
B22: Period | C22: 1 | D22: 2 | E22: 3 | F22: 4 | G22: 5 | H22: 6 | I22: 6
B23: Years to discount | C23: =C18 -> 0.5 | D23: =D18 -> 1.5 | E23: =E18 -> 2.5 | F23: =F18 -> 3.5 | G23: =G18 -> 4.5 | H23: =H18 -> 5.5 | I23: =I18 -> 5.5
B24: Present values with terminal value from a multiple | C24: =C14/(1+$C$28)^C23 -> #DIV/0! | D24: =D14/(1+$C$28)^D23 -> #DIV/0! | E24: =E14/(1+$C$28)^E23 -> #DIV/0! | F24: =F14/(1+$C$28)^F23 -> #DIV/0! | G24: =G14/(1+$C$28)^G23 -> #DIV/0! | H24: =H14/(1+$C$28)^H23 -> #DIV/0! | I24: =I14/(1+$C$28)^I23 -> #DIV/0!
B26: Valuation Analysis
B27: Terminal growth rate | C27: ='DCF_-_FCFF_timing'!C27 -> 0.01
B28: WACC | C28: ='DCF_-_FCFF_timing'!C28 -> #DIV/0!
B29: Terminal EV/EBITDA | C29: ='DCF_-_FCFF_timing'!C29 -> 8
B31: Date of end of historical period | C31: ='DCF_-_FCFF_timing'!C31 -> 0
B32: Valuation date | C32: ='DCF_-_FCFF_timing'!C32 -> 0
B36: Terminal value (as a perpetuity)
B37: Estimated enterprise value (as of valuation date) | C37: =SUM(C19:I19) -> #DIV/0!
B38: Value of net debt (at end of historical period) | C38: ='DCF_-_FCFF_timing'!C38 -> 0
B39: Estimated equity value (as of valuation date) | C39: =C37-C38 -> #DIV/0! | E39: ='DCF_-_FCFF_341'!C36 -> #DIV/0! | F39: =(C41/E39)-1 -> #DIV/0! | G39: 341
B40: Weighted average basic shares outstanding (in millions, end of historical period) | C40: ='DCF_-_FCFF_timing'!C40 -> 0 | E40: ='DCF_-_FCFF_timing'!C41 -> #DIV/0! | F40: =C41/E40-1 -> #DIV/0! | G40: timing
B41: Estimated price per share (as of valuation date) | C41: =C39/C40 -> #DIV/0!
B43: Terminal value (from a multiple)
B44: Estimated enterprise value (as of valuation date) | C44: =SUM(C24:I24) -> #DIV/0! | E44: ='DCF_-_FCFF_341'!C45 -> #DIV/0! | F44: =C48/E44-1 -> #DIV/0! | G44: 341
B45: Value of net debt (at end of historical period) | C45: =C38 -> 0 | E45: ='DCF_-_FCFF_timing'!C48 -> #DIV/0! | F45: =C48/E45-1 -> #DIV/0! | G45: timing
B46: Estimated equity value (as of valuation date) | C46: =C44-C45 -> #DIV/0!
B47: Weighted average basic shares outstanding (in millions, end of historical period) | C47: ='DCF_-_FCFF_timing'!C47 -> 0
B48: Estimated price per share (as of valuation date) | C48: =C46/C47 -> #DIV/0!
B50: Company Name | C50: LTM EBIT | D50: LTM Total Revenue | E50: EBIT/sales | F50: LTM EBITDA
...

Sheet DCF_-_FCFE_341
B1: DCF Analysis | C1: Forecast yr 1 | D1: Forecast yr 2 | E1: Forecast yr 3 | F1: Forecast yr 4 | G1: Forecast yr 5 | H1: Forecast yr 6 | I1: Terminal
B2: FCFE & Terminal Value
