Workbook

Sheet Input Data
B1: Property Overview
B2: Property Name | C2: Property Type | D2: Units | E2: Year Built | F2: Occupancy rate | G2: Market | I2: Average Unit Side | J2: Appraised Value | M2: Custom Amort and Loan Length Inputs
B3: Test Property 1 | C3: Garden Style Multifamily | D3: 96 | E3: 1998 | F3: 0.93 | G3: Secondary metro, growing pop | I3: 900 Sq Ft | J3: 16800000 | M3: Select Custom Inputs in B25 and E25 to enable
M4: Custom Loan Length (Years) | N4: 22
M5: Custom Amortization Period (Years) | N5: 25
B6: Income Assumptions
B7: Average In-place rent | C7: Market Rent | D7: Economic Vacancy | E7: Other income (as a % of gross potential rent) | H7: Annual rent growth
B8: 1425 | C8: 1500 | D8: 0.07 | E8: 0.03 | H8: 0.0275
B10: Operating Expenses | D10: As a % of EGI | H10: $ Per unit per year | M10: ARM Mode Enabled?
B11: Reparis & maintenance | C11: payroll & admin | D11: Utilities | E11: management fee | F11: Property taxes (as a % of purchase price) | H11: insurance | I11: replacement reserves | K11: Tax Rate | M11: Green = Yes Red = No
B12: 0.06 | C12: 0.05 | D12: 0.075 | E12: 0.05 | F12: 0.0125 | H12: 425 | I12: 300 | K12: 0.22
B15: Acquisition assumptions
B16: Purchase Price (including fees) | C16: Down Payment | D16: Selling Cost (as a % of sale) | E16: Exit Cap Rate | M16: ARM Rate Adjustments
B17: 16800000 | C17: 0.4 | D17: 0.02 | E17: 0.065 | M17: Month of adjustment | N17: New annual rate
M18: 30 | N18: 0.06
B21: Debt Terms
B22: Loan Length | C22: Fixed or Adjustable rate | D22: Interest Rate (annual) | E22: Amortization Length
B23: =$N$4 -> 22 | C23: ARM | D23: 0.0635 | E23: =$N$5 -> 25
B25: Limits On Loan
B26: Minimum DSCR | C26: Maximum LTV | D26: Minimum Debt Yield
B27: 1.25 | C27: 0.65 | D27: 0.0875

Sheet Debt calculations
A2: ARM Adjustment check | B2: Interest rate | C2: month | D2: Beginning Balance | E2: PMT | F2: After pmt mortgage amount | G2: Interest amount | H2: Principal paid | I2: End of Month Balance | J2: Prepayment of Loan In $ (manual input to adjust for prepayment of loan)
A3: =IF(('Input Data'!$C$23)="FRM", FALSE, ISNUMBER(MATCH(C3,'Input Data'!$M$18:$M$30,0))) -> FALSE | B3: ='Input Data'!$D$23 -> 0.0635 | C3: 1 | D3: ='Input Data'!B17*(1-'Input Data'!C17) -> 10080000 | E3: =IF('Input Data'!E23=0,G3,IF(OR(D3<=0,C3>'Input Data'!$B$23*12),0,IF(AND(C3='Input Data'!$B$23*12,'Input Data'!$E$23>'Input Data'!$B$23),D3+D3*B3/12,IF('Input Data'!$C$23="FRM",-PMT($B$3/12,'Input Data'!$E$23*12,$D$3),IF($A3,-PMT(B3/12,('Input Data'!$E$23*12)-C3+1,D3),-PMT(B3/12,'Input Data'!E23*12,'Debt calculations'!D3)))))) -> 67119.121 | F3: =IF(D3-E3<0,0,D3-E3) -> 10012881 | G3: =IF(C3>'Input Data'!$B$23*12,0,D3*B3/12) -> 53340 | H3: =MIN(E3-G3,D3) -> 13779.121 | I3: =IF(ROUND(D3-H3,2)=0,0,D3-H3) -> 10066221
A4: =IF(('Input Data'!$C$23)="FRM", FALSE, ISNUMBER(MATCH(C4,'Input Data'!$M$18:$M$30,0))) -> FALSE | B4: =IF($A4, _xlfn.XLOOKUP(C4,'Input Data'!$M$17:$M$29,'Input Data'!$N$17:$N$29),$B3) -> 0.0635 | C4: =C3+1 -> 2 | D4: =IF(I3>0,I3-J3,0) -> 10066221 | E4: =IF('Input Data'!$E$23=0,G4,IF(OR(D4<=0,C4>'Input Data'!$B$23*12),0,IF(AND(C4='Input Data'!$B$23*12,'Input Data'!$E$23>'Input Data'!$B$23),D4+D4*B4/12,IF('Input Data'!$C$23="FRM",-PMT($B$3/12,'Input Data'!$E$23*12,$D$3),IF($A4,-PMT(B4/12,('Input Data'!$E$23*12)-C4+1,D4),E3))))) -> 67119.121 | F4: =IF(D4-E4<0,0,D4-E4) -> 9999101.8 | G4: =IF(C4>'Input Data'!$B$23*12,0,D4*B4/12) -> 53267.085 | H4: =MIN(E4-G4,D4) -> 13852.035 | I4: =IF(ROUND(D4-H4,2)=0,0,D4-H4) -> 10052369
A5: =IF(('Input Data'!$C$23)="FRM", FALSE, ISNUMBER(MATCH(C5,'Input Data'!$M$18:$M$30,0))) -> FALSE | B5: =IF($A5, _xlfn.XLOOKUP(C5,'Input Data'!$M$17:$M$29,'Input Data'!$N$17:$N$29),$B4) -> 0.0635 | C5: =C4+1 -> 3 | D5: =IF(I4>0,I4-J4,0) -> 10052369 | E5: =IF('Input Data'!$E$23=0,G5,IF(OR(D5<=0,C5>'Input Data'!$B$23*12),0,IF(AND(C5='Input Data'!$B$23*12,'Input Data'!$E$23>'Input Data'!$B$23),D5+D5*B5/12,IF('Input Data'!$C$23="FRM",-PMT($B$3/12,'Input Data'!$E$23*12,$D$3),IF($A5,-PMT(B5/12,('Input Data'!$E$23*12)-C5+1,D5),E4))))) -> 67119.121 | F5: =IF(D5-E5<0,0,D5-E5) -> 9985249.7 | G5: =IF(C5>'Input Data'!$B$23*12,0,D5*B5/12) -> 53193.785 | H5: =MIN(E5-G5,D5) -> 13925.336 | I5: =IF(ROUND(D5-H5,2)=0,0,D5-H5) -> 10038444
A6: =IF(('Input Data'!$C$23)="FRM", FALSE, ISNUMBER(MATCH(C6,'Input Data'!$M$18:$M$30,0))) -> FALSE | B6: =IF($A6, _xlfn.XLOOKUP(C6,'Input Data'!$M$17:$M$29,'Input Data'!$N$17:$N$29),$B5) -> 0.0635 | C6: =C5+1 -> 4 | D6: =IF(I5>0,I5-J5,0) -> 10038444 | E6: =IF('Input Data'!$E$23=0,G6,IF(OR(D6<=0,C6>'Input Data'!$B$23*12),0,IF(AND(C6='Input Data'!$B$23*12,'Input Data'!$E$23>'Input Data'!$B$23),D6+D6*B6/12,IF('Input Data'!$C$23="FRM",-PMT($B$3/12,'Input Data'!$E$23*12,$D$3),IF($A6,-PMT(B6/12,('Input Data'!$E$23*12)-C6+1,D6),E5))))) -> 67119.121 | F6: =IF(D6-E6<0,0,D6-E6) -> 9971324.4 | G6: =IF(C6>'Input Data'!$B$23*12,0,D6*B6/12) -> 53120.097 | H6: =MIN(E6-G6,D6) -> 13999.024 | I6: =IF(ROUND(D6-H6,2)=0,0,D6-H6) -> 10024444
A7: =IF(('Input Data'!$C$23)="FRM", FALSE, ISNUMBER(MATCH(C7,'Input Data'!$M$18:$M$30,0))) -> FALSE | B7: =IF($A7, _xlfn.XLOOKUP(C7,'Input Data'!$M$17:$M$29,'Input Data'!$N$17:$N$29),$B6) -> 0.0635 | C7: =C6+1 -> 5 | D7: =IF(I6>0,I6-J6,0) -> 10024444 | E7: =IF('Input Data'!$E$23=0,G7,IF(OR(D7<=0,C7>'Input Data'!$B$23*12),0,IF(AND(C7='Input Data'!$B$23*12,'Input Data'!$E$23>'Input Data'!$B$23),D7+D7*B7/12,IF('Input Data'!$C$23="FRM",-PMT($B$3/12,'Input Data'!$E$23*12,$D$3),IF($A7,-PMT(B7/12,('Input Data'!$E$23*12)-C7+1,D7),E6))))) -> 67119.121 | F7: =IF(D7-E7<0,0,D7-E7) -> 9957325.4 | G7: =IF(C7>'Input Data'!$B$23*12,0,D7*B7/12) -> 53046.019 | H7: =MIN(E7-G7,D7) -> 14073.102 | I7: =IF(ROUND(D7-H7,2)=0,0,D7-H7) -> 10010371
A8: =IF(('Input Data'!$C$23)="FRM", FALSE, ISNUMBER(MATCH(C8,'Input Data'!$M$18:$M$30,0))) -> FALSE | B8: =IF($A8, _xlfn.XLOOKUP(C8,'Input Data'!$M$17:$M$29,'Input Data'!$N$17:$N$29),$B7) -> 0.0635 | C8: =C7+1 -> 6 | D8: =IF(I7>0,I7-J7,0) -> 10010371 | E8: =IF('Input Data'!$E$23=0,G8,IF(OR(D8<=0,C8>'Input Data'!$B$23*12),0,IF(AND(C8='Input Data'!$B$23*12,'Input Data'!$E$23>'Input Data'!$B$23),D8+D8*B8/12,IF('Input Data'!$C$23="FRM",-PMT($B$3/12,'Input Data'!$E$23*12,$D$3),IF($A8,-PMT(B8/12,('Input Data'!$E$23*12)-C8+1,D8),E7))))) -> 67119.121 | F8: =IF(D8-E8<0,0,D8-E8) -> 9943252.3 | G8: =IF(C8>'Input Data'!$B$23*12,0,D8*B8/12) -> 52971.549 | H8: =MIN(E8-G8,D8) -> 14147.572 | I8: =IF(ROUND(D8-H8,2)=0,0,D8-H8) -> 9996223.8
A9: =IF(('Input Data'!$C$23)="FRM", FALSE, ISNUMBER(MATCH(C9,'Input Data'!$M$18:$M$30,0))) -> FALSE | B9: =IF($A9, _xlfn.XLOOKUP(C9,'Input Data'!$M$17:$M$29,'Input Data'!$N$17:$N$29),$B8) -> 0.0635 | C9: =C8+1 -> 7 | D9: =IF(I8>0,I8-J8,0) -> 9996223.8 | E9: =IF('Input Data'!$E$23=0,G9,IF(OR(D9<=0,C9>'Input Data'!$B$23*12),0,IF(AND(C9='Input Data'!$B$23*12,'Input Data'!$E$23>'Input Data'!$B$23),D9+D9*B9/12,IF('Input Data'!$C$23="FRM",-PMT($B$3/12,'Input Data'!$E$23*12,$D$3),IF($A9,-PMT(B9/12,('Input Data'!$E$23*12)-C9+1,D9),E8))))) -> 67119.121 | F9: =IF(D9-E9<0,0,D9-E9) -> 9929104.7 | G9: =IF(C9>'Input Data'!$B$23*12,0,D9*B9/12) -> 52896.684 | H9: =MIN(E9-G9,D9) -> 14222.437 | I9: =IF(ROUND(D9-H9,2)=0,0,D9-H9) -> 9982001.4 | L9: Loan Maturity Month | M9: =12*'Input Data'!B23 -> 264
A10: =IF(('Input Data'!$C$23)="FRM", FALSE, ISNUMBER(MATCH(C10,'Input Data'!$M$18:$M$30,0))) -> FALSE | B10: =IF($A10, _xlfn.XLOOKUP(C10,'Input Data'!$M$17:$M$29,'Input Data'!$N$17:$N$29),$B9) -> 0.0635 | C10: =C9+1 -> 8 | D10: =IF(I9>0,I9-J9,0) -> 9982001.4 | E10: =IF('Input Data'!$E$23=0,G10,IF(OR(D10<=0,C10>'Input Data'!$B$23*12),0,IF(AND(C10='Input Data'!$B$23*12,'Input Data'!$E$23>'Input Data'!$B$23),D10+D10*B10/12,IF('Input Data'!$C$23="FRM",-PMT($B$3/12,'Input Data'!$E$23*12,$D$3),IF($A10,-PMT(B10/12,('Input Data'!$E$23*12)-C10+1,D10),E9))))) -> 67119.121 | F10: =IF(D10-E10<0,0,D10-E10) -> 9914882.3 | G10: =IF(C10>'Input Data'!$B$23*12,0,D10*B10/12) -> 52821.424 | H10: =MIN(E10-G10,D10) -> 14297.697 | I10: =IF(ROUND(D10-H10,2)=0,0,D10-H10) -> 9967703.7 | L10: balloon payment | M10: =IF('Input Data'!$E$23<='Input Data'!$B$23,"No Balloon Payment",_xlfn.XLOOKUP(M9,C3:C362,E3:E362,"Value Not Found")) -> 2204814.5
A11: =IF(('Input Data'!$C$23)="FRM", FALSE, ISNUMBER(MATCH(C11,'Input Data'!$M$18:$M$30,0))) -> FALSE | B11: =IF($A11, _xlfn.XLOOKUP(C11,'Input Data'!$M$17:$M$29,'Input Data'!$N$17:$N$29),$B10) -> 0.0635 | C11: =C10+1 -> 9 | D11: =IF(I10>0,I10-J10,0) -> 9967703.7 | E11: =IF('Input Data'!$E$23=0,G11,IF(OR(D11<=0,C11>'Input Data'!$B$23*12),0,IF(AND(C11='Input Data'!$B$23*12,'Input Data'!$E$23>'Input Data'!$B$23),D11+D11*B11/12,IF('Input Data'!$C$23="FRM",-PMT($B$3/12,'Input Data'!$E$23*12,$D$3),IF($A11,-PMT(B11/12,('Input Data'!$E$23*12)-C11+1,D11),E10))))) -> 67119.121 | F11: =IF(D11-E11<0,0,D11-E11) -> 9900584.6 | G11: =IF(C11>'Input Data'!$B$23*12,0,D11*B11/12) -> 52745.765 | H11: =MIN(E11-G11,D11) -> 14373.356 | I11: =IF(ROUND(D11-H11,2)=0,0,D11-H11) -> 9953330.3
A12: =IF(('Input Data'!$C$23)="FRM", FALSE, ISNUMBER(MATCH(C12,'Input Data'!$M$18:$M$30,0))) -> FALSE | B12: =IF($A12, _xlfn.XLOOKUP(C12,'Input Data'!$M$17:$M$29,'Input Data'!$N$17:$N$29),$B11) -> 0.0635 | C12: =C11+1 -> 10 | D12: =IF(I11>0,I11-J11,0) -> 9953330.3 | E12: =IF('Input Data'!$E$23=0,G12,IF(OR(D12<=0,C12>'Input Data'!$B$23*12),0,IF(AND(C12='Input Data'!$B$23*12,'Input Data'!$E$23>'Input Data'!$B$23),D12+D12*B12/12,IF('Input Data'!$C$23="FRM",-PMT($B$3/12,'Input Data'!$E$23*12,$D$3),IF($A12,-PMT(B12/12,('Input Data'!$E$23*12)-C12+1,D12),E11))))) -> 67119.121 | F12: =IF(D12-E12<0,0,D12-E12) -> 9886211.2 | G12: =IF(C12>'Input Data'!$B$23*12,0,D12*B12/12) -> 52669.706 | H12: =MIN(E12-G12,D12) -> 14449.415 | I12: =IF(ROUND(D12-H12,2)=0,0,D12-H12) -> 9938880.9
A13: =IF(('Input Data'!$C$23)="FRM", FALSE, ISNUMBER(MATCH(C13,'Input Data'!$M$18:$M$30,0))) -> FALSE | B13: =IF($A13, _xlfn.XLOOKUP(C13,'Input Data'!$M$17:$M$29,'Input Data'!$N$17:$N$29),$B12) -> 0.0635 | C13: =C12+1 -> 11 | D13: =IF(I12>0,I12-J12,0) -> 9938880.9 | E13: =IF('Input Data'!$E$23=0,G13,IF(OR(D13<=0,C13>'Input Data'!$B$23*12),0,IF(AND(C13='Input Data'!$B$23*12,'Input Data'!$E$23>'Input Data'!$B$23),D13+D13*B13/12,IF('Input Data'!$C$23="FRM",-PMT($B$3/12,'Input Data'!$E$23*12,$D$3),IF($A13,-PMT(B13/12,('Input Data'!$E$23*12)-C13+1,D13),E12))))) -> 67119.121 | F13: =IF(D13-E13<0,0,D13-E13) -> 9871761.8 | G13: =IF(C13>'Input Data'!$B$23*12,0,D13*B13/12) -> 52593.245 | H13: =MIN(E13-G13,D13) -> 14525.876 | I13: =IF(ROUND(D13-H13,2)=0,0,D13-H13) -> 9924355
A14: =IF(('Input Data'!$C$23)="FRM", FALSE, ISNUMBER(MATCH(C14,'Input Data'!$M$18:$M$30,0))) -> FALSE | B14: =IF($A14, _xlfn.XLOOKUP(C14,'Input Data'!$M$17:$M$29,'Input Data'!$N$17:$N$29),$B13) -> 0.0635 | C14: =C13+1 -> 12 | D14: =IF(I13>0,I13-J13,0) -> 9924355 | E14: =IF('Input Data'!$E$23=0,G14,IF(OR(D14<=0,C14>'Input Data'!$B$23*12),0,IF(AND(C14='Input Data'!$B$23*12,'Input Data'!$E$23>'Input Data'!$B$23),D14+D14*B14/12,IF('Input Data'!$C$23="FRM",-PMT($B$3/12,'Input Data'!$E$23*12,$D$3),IF($A14,-PMT(B14/12,('Input Data'!$E$23*12)-C14+1,D14),E13))))) -> 67119.121 | F14: =IF(D14-E14<0,0,D14-E14) -> 9857235.9 | G14: =IF(C14>'Input Data'!$B$23*12,0,D14*B14/12) -> 52516.379 | H14: =MIN(E14-G14,D14) -> 14602.742 | I14: =IF(ROUND(D14-H14,2)=0,0,D14-H14) -> 9909752.3
A15: =IF(('Input Data'!$C$23)="FRM", FALSE, ISNUMBER(MATCH(C15,'Input Data'!$M$18:$M$30,0))) -> FALSE | B15: =IF($A15, _xlfn.XLOOKUP(C15,'Input Data'!$M$17:$M$29,'Input Data'!$N$17:$N$29),$B14) -> 0.0635 | C15: =C14+1 -> 13 | D15: =IF(I14>0,I14-J14,0) -> 9909752.3 | E15: =IF('Input Data'!$E$23=0,G15,IF(OR(D15<=0,C15>'Input Data'!$B$23*12),0,IF(AND(C15='Input Data'!$B$23*12,'Input Data'!$E$23>'Input Data'!$B$23),D15+D15*B15/12,IF('Input Data'!$C$23="FRM",-PMT($B$3/12,'Input Data'!$E$23*12,$D$3),IF($A15,-PMT(B15/12,('Input Data'!$E$23*12)-C15+1,D15),E14))))) -> 67119.121 | F15: =IF(D15-E15<0,0,D15-E15) -> 9842633.2 | G15: =IF(C15>'Input Data'!$B$23*12,0,D15*B15/12) -> 52439.106 | H15: =MIN(E15-G15,D15) -> 14680.015 | I15: =IF(ROUND(D15-H15,2)=0,0,D15-H15) -> 9895072.3
A16: =IF(('Input Data'!$C$23)="FRM", FALSE, ISNUMBER(MATCH(C16,'Input Data'!$M$18:$M$30,0))) -> FALSE | B16: =IF($A16, _xlfn.XLOOKUP(C16,'Input Data'!$M$17:$M$29,'Input Data'!$N$17:$N$29),$B15) -> 0.0635 | C16: =C15+1 -> 14 | D16: =IF(I15>0,I15-J15,0) -> 9895072.3 | E16: =IF('Input Data'!$E$23=0,G16,IF(OR(D16<=0,C16>'Input Data'!$B$23*12),0,IF(AND(C16='Input Data'!$B$23*12,'Input Data'!$E$23>'Input Data'!$B$23),D16+D16*B16/12,IF('Input Data'!$C$23="FRM",-PMT($B$3/12,'Input Data'!$E$23*12,$D$3),IF($A16,-PMT(B16/12,('Input Data'!$E$23*12)-C16+1,D16),E15))))) -> 67119.121 | F16: =IF(D16-E16<0,0,D16-E16) -> 9827953.2 | G16: =IF(C16>'Input Data'!$B$23*12,0,D16*B16/12) -> 52361.424 | H16: =MIN(E16-G16,D16) -> 14757.697 | I16: =IF(ROUND(D16-H16,2)=0,0,D16-H16) -> 9880314.6
A17: =IF(('Input Data'!$C$23)="FRM", FALSE, ISNUMBER(MATCH(C17,'Input Data'!$M$18:$M$30,0))) -> FALSE | B17: =IF($A17, _xlfn.XLOOKUP(C17,'Input Data'!$M$17:$M$29,'Input Data'!$N$17:$N$29),$B16) -> 0.0635 | C17: =C16+1 -> 15 | D17: =IF(I16>0,I16-J16,0) -> 9880314.6 | E17: =IF('Input Data'!$E$23=0,G17,IF(OR(D17<=0,C17>'Input Data'!$B$23*12),0,IF(AND(C17='Input Data'!$B$23*12,'Input Data'!$E$23>'Input Data'!$B$23),D17+D17*B17/12,IF('Input Data'!$C$23="FRM",-PMT($B$3/12,'Input Data'!$E$23*12,$D$3),IF($A17,-PMT(B17/12,('Input Data'!$E$23*12)-C17+1,D17),E16))))) -> 67119.121 | F17: =IF(D17-E17<0,0,D17-E17) -> 9813195.5 | G17: =IF(C17>'Input Data'!$B$23*12,0,D17*B17/12) -> 52283.331 | H17: =MIN(E17-G17,D17) -> 14835.79 | I17: =IF(ROUND(D17-H17,2)=0,0,D17-H17) -> 9865478.8
A18: =IF(('Input Data'!$C$23)="FRM", FALSE, ISNUMBER(MATCH(C18,'Input Data'!$M$18:$M$30,0))) -> FALSE | B18: =IF($A18, _xlfn.XLOOKUP(C18,'Input Data'!$M$17:$M$29,'Input Data'!$N$17:$N$29),$B17) -> 0.0635 | C18: =C17+1 -> 16 | D18: =IF(I17>0,I17-J17,0) -> 9865478.8 | E18: =IF('Input Data'!$E$23=0,G18,IF(OR(D18<=0,C18>'Input Data'!$B$23*12),0,IF(AND(C18='Input Data'!$B$23*12,'Input Data'!$E$23>'Input Data'!$B$23),D18+D18*B18/12,IF('Input Data'!$C$23="FRM",-PMT($B$3/12,'Input Data'!$E$23*12,$D$3),IF($A18,-PMT(B18/12,('Input Data'!$E$23*12)-C18+1,D18),E17))))) -> 67119.121 | F18: =IF(D18-E18<0,0,D18-E18) -> 9798359.7 | G18: =IF(C18>'Input Data'!$B$23*12,0,D18*B18/12) -> 52204.825 | H18: =MIN(E18-G18,D18) -> 14914.296 | I18: =IF(ROUND(D18-H18,2)=0,0,D18-H18) -> 9850564.5
A19: =IF(('Input Data'!$C$23)="FRM", FALSE, ISNUMBER(MATCH(C19,'Input Data'!$M$18:$M$30,0))) -> FALSE | B19: =IF($A19, _xlfn.XLOOKUP(C19,'Input Data'!$M$17:$M$29,'Input Data'!$N$17:$N$29),$B18) -> 0.0635 | C19: =C18+1 -> 17 | D19: =IF(I18>0,I18-J18,0) -> 9850564.5 | E19: =IF('Input Data'!$E$23=0,G19,IF(OR(D19<=0,C19>'Input Data'!$B$23*12),0,IF(AND(C19='Input Data'!$B$23*12,'Input Data'!$E$23>'Input Data'!$B$23),D19+D19*B19/12,IF('Input Data'!$C$23="FRM",-PMT($B$3/12,'Input Data'!$E$23*12,$D$3),IF($A19,-PMT(B19/12,('Input Data'!$E$23*12)-C19+1,D19),E18))))) -> 67119.121 | F19: =IF(D19-E19<0,0,D19-E19) -> 9783445.4 | G19: =IF(C19>'Input Data'!$B$23*12,0,D19*B19/12) -> 52125.904 | H19: =MIN(E19-G19,D19) -> 14993.217 | I19: =IF(ROUND(D19-H19,2)=0,0,D19-H19) -> 9835571.3
A20: =IF(('Input Data'!$C$23)="FRM", FALSE, ISNUMBER(MATCH(C20,'Input Data'!$M$18:$M$30,0))) -> FALSE | B20: =IF($A20, _xlfn.XLOOKUP(C20,'Input Data'!$M$17:$M$29,'Input Data'!$N$17:$N$29),$B19) -> 0.0635 | C20: =C19+1 -> 18 | D20: =IF(I19>0,I19-J19,0) -> 9835571.3 | E20: =IF('Input Data'!$E$23=0,G20,IF(OR(D20<=0,C20>'Input Data'!$B$23*12),0,IF(AND(C20='Input Data'!$B$23*12,'Input Data'!$E$23>'Input Data'!$B$23),D20+D20*B20/12,IF('Input Data'!$C$23="FRM",-PMT($B$3/12,'Input Data'!$E$23*12,$D$3),IF($A20,-PMT(B20/12,('Input Data'!$E$23*12)-C20+1,D20),E19))))) -> 67119.121 | F20: =IF(D20-E20<0,0,D20-E20) -> 9768452.2 | G20: =IF(C20>'Input Data'!$B$23*12,0,D20*B20/12) -> 52046.565 | H20: =MIN(E20-G20,D20) -> 15072.556 | I20: =IF(ROUND(D20-H20,2)=0,0,D20-H20) -> 9820498.7
A21: =IF(('Input Data'!$C$23)="FRM", FALSE, ISNUMBER(MATCH(C21,'Input Data'!$M$18:$M$30,0))) -> FALSE | B21: =IF($A21, _xlfn.XLOOKUP(C21,'Input Data'!$M$17:$M$29,'Input Data'!$N$17:$N$29),$B20) -> 0.0635 | C21: =C20+1 -> 19 | D21: =IF(I20>0,I20-J20,0) -> 9820498.7 | E21: =IF('Input Data'!$E$23=0,G21,IF(OR(D21<=0,C21>'Input Data'!$B$23*12),0,IF(AND(C21='Input Data'!$B$23*12,'Input Data'!$E$23>'Input Data'!$B$23),D21+D21*B21/12,IF('Input Data'!$C$23="FRM",-PMT($B$3/12,'Input Data'!$E$23*12,$D$3),IF($A21,-PMT(B21/12,('Input Data'!$E$23*12)-C21+1,D21),E20))))) -> 67119.121 | F21: =IF(D21-E21<0,0,D21-E21) -> 9753379.6 | G21: =IF(C21>'Input Data'!$B$23*12,0,D21*B21/12) -> 51966.806 | H21: =MIN(E21-G21,D21) -> 15152.315 | I21: =IF(ROUND(D21-H21,2)=0,0,D21-H21) -> 9805346.4 | L21: PMT calculator explained in english
A22: =IF(('Input Data'!$C$23)="FRM", FALSE, ISNUMBER(MATCH(C22,'Input Data'!$M$18:$M$30,0))) -> FALSE | B22: =IF($A22, _xlfn.XLOOKUP(C22,'Input Data'!$M$17:$M$29,'Input Data'!$N$17:$N$29),$B21) -> 0.0635 | C22: =C21+1 -> 20 | D22: =IF(I21>0,I21-J21,0) -> 9805346.4 | E22: =IF('Input Data'!$E$23=0,G22,IF(OR(D22<=0,C22>'Input Data'!$B$23*12),0,IF(AND(C22='Input Data'!$B$23*12,'Input Data'!$E$23>'Input Data'!$B$23),D22+D22*B22/12,IF('Input Data'!$C$23="FRM",-PMT($B$3/12,'Input Data'!$E$23*12,$D$3),IF($A22,-PMT(B22/12,('Input Data'!$E$23*12)-C22+1,D22),E21))))) -> 67119.121 | F22: =IF(D22-E22<0,0,D22-E22) -> 9738227.3 | G22: =IF(C22>'Input Data'!$B$23*12,0,D22*B22/12) -> 51886.625 | H22: =MIN(E22-G22,D22) -> 15232.496 | I22: =IF(ROUND(D22-H22,2)=0,0,D22-H22) -> 9790113.9 | L22: If Amortization is 0 years (a non-amortizing loan), set the pmt to the interest amount, if it is not 0, check if both the remaining balance is less than or equal to 0 and the month count has not exceeded that of the loan duration, if either of those is true, set payment to 0, if false, check for both if the month of the payment is the same as the last month of loan duration and that the amortization length is longer than the loan duration. if both are true, the full balance plus interest is due. If false, check if the loan is a FRM or ARM loan, if it is FRM, calculate the PMT, if it is not, will be an ARM, using the A column, read when to adjust interest rates)
A23: =IF(('Input Data'!$C$23)="FRM", FALSE, ISNUMBER(MATCH(C23,'Input Data'!$M$18:$M$30,0))) -> FALSE | B23: =IF($A23, _xlfn.XLOOKUP(C23,'Input Data'!$M$17:$M$29,'Input Data'!$N$17:$N$29),$B22) -> 0.0635 | C23: =C22+1 -> 21 | D23: =IF(I22>0,I22-J22,0) -> 9790113.9 | E23: =IF('Input Data'!$E$23=0,G23,IF(OR(D23<=0,C23>'Input Data'!$B$23*12),0,IF(AND(C23='Input Data'!$B$23*12,'Input Data'!$E$23>'Input Data'!$B$23),D23+D23*B23/12,IF('Input Data'!$C$23="FRM",-PMT($B$3/12,'Input Data'!$E$23*12,$D$3),IF($A23,-PMT(B23/12,('Input Data'!$E$23*12)-C23+1,D23),E22))))) -> 67119.121 | F23: =IF(D23-E23<0,0,D23-E23) -> 9722994.8 | G23: =IF(C23>'Input Data'!$B$23*12,0,D23*B23/12) -> 51806.019 | H23: =MIN(E23-G23,D23) -> 15313.101 | I23: =IF(ROUND(D23-H23,2)=0,0,D23-H23) -> 9774800.8
A24: =IF(('Input Data'!$C$23)="FRM", FALSE, ISNUMBER(MATCH(C24,'Input Data'!$M$18:$M$30,0))) -> FALSE | B24: =IF($A24, _xlfn.XLOOKUP(C24,'Input Data'!$M$17:$M$29,'Input Data'!$N$17:$N$29),$B23) -> 0.0635 | C24: =C23+1 -> 22 | D24: =IF(I23>0,I23-J23,0) -> 9774800.8 | E24: =IF('Input Data'!$E$23=0,G24,IF(OR(D24<=0,C24>'Input Data'!$B$23*12),0,IF(AND(C24='Input Data'!$B$23*12,'Input Data'!$E$23>'Input Data'!$B$23),D24+D24*B24/12,IF('Input Data'!$C$23="FRM",-PMT($B$3/12,'Input Data'!$E$23*12,$D$3),IF($A24,-PMT(B24/12,('Input Data'!$E$23*12)-C24+1,D24),E23))))) -> 67119.121 | F24: =IF(D24-E24<0,0,D24-E24) -> 9707681.7 | G24: =IF(C24>'Input Data'!$B$23*12,0,D24*B24/12) -> 51724.988 | H24: =MIN(E24-G24,D24) -> 15394.133 | I24: =IF(ROUND(D24-H24,2)=0,0,D24-H24) -> 9759406.7
A25: =IF(('Input Data'!$C$23)="FRM", FALSE, ISNUMBER(MATCH(C25,'Input Data'!$M$18:$M$30,0))) -> FALSE | B25: =IF($A25, _xlfn.XLOOKUP(C25,'Input Data'!$M$17:$M$29,'Input Data'!$N$17:$N$29),$B24) -> 0.0635 | C25: =C24+1 -> 23 | D25: =IF(I24>0,I24-J24,0) -> 9759406.7 | E25: =IF('Input Data'!$E$23=0,G25,IF(OR(D25<=0,C25>'Input Data'!$B$23*12),0,IF(AND(C25='Input Data'!$B$23*12,'Input Data'!$E$23>'Input Data'!$B$23),D25+D25*B25/12,IF('Input Data'!$C$23="FRM",-PMT($B$3/12,'Input Data'!$E$23*12,$D$3),IF($A25,-PMT(B25/12,('Input Data'!$E$23*12)-C25+1,D25),E24))))) -> 67119.121 | F25: =IF(D25-E25<0,0,D25-E25) -> 9692287.6 | G25: =IF(C25>'Input Data'!$B$23*12,0,D25*B25/12) -> 51643.527 | H25: =MIN(E25-G25,D25) -> 15475.594 | I25: =IF(ROUND(D25-H25,2)=0,0,D25-H25) -> 9743931.1
A26: =IF(('Input Data'!$C$23)="FRM", FALSE, ISNUMBER(MATCH(C26,'Input Data'!$M$18:$M$30,0))) -> FALSE | B26: =IF($A26, _xlfn.XLOOKUP(C26,'Input Data'!$M$17:$M$29,'Input Data'!$N$17:$N$29),$B25) -> 0.0635 | C26: =C25+1 -> 24 | D26: =IF(I25>0,I25-J25,0) -> 9743931.1 | E26: =IF('Input Data'!$E$23=0,G26,IF(OR(D26<=0,C26>'Input Data'!$B$23*12),0,IF(AND(C26='Input Data'!$B$23*12,'Input Data'!$E$23>'Input Data'!$B$23),D26+D26*B26/12,IF('Input Data'!$C$23="FRM",-PMT($B$3/12,'Input Data'!$E$23*12,$D$3),IF($A26,-PMT(B26/12,('Input Data'!$E$23*12)-C26+1,D26),E25))))) -> 67119.121 | F26: =IF(D26-E26<0,0,D26-E26) -> 9676812 | G26: =IF(C26>'Input Data'!$B$23*12,0,D26*B26/12) -> 51561.635 | H26: =MIN(E26-G26,D26) -> 15557.486 | I26: =IF(ROUND(D26-H26,2)=0,0,D26-H26) -> 9728373.6
A27: =IF(('Input Data'!$C$23)="FRM", FALSE, ISNUMBER(MATCH(C27,'Input Data'!$M$18:$M$30,0))) -> FALSE | B27: =IF($A27, _xlfn.XLOOKUP(C27,'Input Data'!$M$17:$M$29,'Input Data'!$N$17:$N$29),$B26) -> 0.0635 | C27: =C26+1 -> 25 | D27: =IF(I26>0,I26-J26,0) -> 9728373.6 | E27: =IF('Input Data'!$E$23=0,G27,IF(OR(D27<=0,C27>'Input Data'!$B$23*12),0,IF(AND(C27='Input Data'!$B$23*12,'Input Data'!$E$23>'Input Data'!$B$23),D27+D27*B27/12,IF('Input Data'!$C$23="FRM",-PMT($B$3/12,'Input Data'!$E$23*12,$D$3),IF($A27,-PMT(B27/12,('Input Data'!$E$23*12)-C27+1,D27),E26))))) -> 67119.121 | F27: =IF(D27-E27<0,0,D27-E27) -> 9661254.5 | G27: =IF(C27>'Input Data'!$B$23*12,0,D27*B27/12) -> 51479.31 | H27: =MIN(E27-G27,D27) -> 15639.811 | I27: =IF(ROUND(D27-H27,2)=0,0,D27-H27) -> 9712733.8
A28: =IF(('Input Data'!$C$23)="FRM", FALSE, ISNUMBER(MATCH(C28,'Input Data'!$M$18:$M$30,0))) -> FALSE | B28: =IF($A28, _xlfn.XLOOKUP(C28,'Input Data'!$M$17:$M$29,'Input Data'!$N$17:$N$29),$B27) -> 0.0635 | C28: =C27+1 -> 26 | D28: =IF(I27>0,I27-J27,0) -> 9712733.8 | E28: =IF('Input Data'!$E$23=0,G28,IF(OR(D28<=0,C28>'Input Data'!$B$23*12),0,IF(AND(C28='Input Data'!$B$23*12,'Input Data'!$E$23>'Input Data'!$B$23),D28+D28*B28/12,IF('Input Data'!$C$23="FRM",-PMT($B$3/12,'Input Data'!$E$23*12,$D$3),IF($A28,-PMT(B28/12,('Input Data'!$E$23*12)-C28+1,D28),E27))))) -> 67119.121 | F28: =IF(D28-E28<0,0,D28-E28) -> 9645614.7 | G28: =IF(C28>'Input Data'!$B$23*12,0,D28*B28/12) -> 51396.55 | H28: =MIN(E28-G28,D28) -> 15722.571 | I28: =IF(ROUND(D28-H28,2)=0,0,D28-H28) -> 9697011.2
A29: =IF(('Input Data'!$C$23)="FRM", FALSE, ISNUMBER(MATCH(C29,'Input Data'!$M$18:$M$30,0))) -> FALSE | B29: =IF($A29, _xlfn.XLOOKUP(C29,'Input Data'!$M$17:$M$29,'Input Data'!$N$17:$N$29),$B28) -> 0.0635 | C29: =C28+1 -> 27 | D29: =IF(I28>0,I28-J28,0) -> 9697011.2 | E29: =IF('Input Data'!$E$23=0,G29,IF(OR(D29<=0,C29>'Input Data'!$B$23*12),0,IF(AND(C29='Input Data'!$B$23*12,'Input Data'!$E$23>'Input Data'!$B$23),D29+D29*B29/12,IF('Input Data'!$C$23="FRM",-PMT($B$3/12,'Input Data'!$E$23*12,$D$3),IF($A29,-PMT(B29/12,('Input Data'!$E$23*12)-C29+1,D29),E28))))) -> 67119.121 | F29: =IF(D29-E29<0,0,D29-E29) -> 9629892.1 | G29: =IF(C29>'Input Data'!$B$23*12,0,D29*B29/12) -> 51313.351 | H29: =MIN(E29-G29,D29) -> 15805.77 | I29: =IF(ROUND(D29-H29,2)=0,0,D29-H29) -> 9681205.4
A30: =IF(('Input Data'!$C$23)="FRM", FALSE, ISNUMBER(MATCH(C30,'Input Data'!$M$18:$M$30,0))) -> FALSE | B30: =IF($A30, _xlfn.XLOOKUP(C30,'Input Data'!$M$17:$M$29,'Input Data'!$N$17:$N$29),$B29) -> 0.0635 | C30: =C29+1 -> 28 | D30: =IF(I29>0,I29-J29,0) -> 9681205.4 | E30: =IF('Input Data'!$E$23=0,G30,IF(OR(D30<=0,C30>'Input Data'!$B$23*12),0,IF(AND(C30='Input Data'!$B$23*12,'Input Data'!$E$23>'Input Data'!$B$23),D30+D30*B30/12,IF('Input Data'!$C$23="FRM",-PMT($B$3/12,'Input Data'!$E$23*12,$D$3),IF($A30,-PMT(B30/12,('Input Data'!$E$23*12)-C30+1,D30),E29))))) -> 67119.121 | F30: =IF(D30-E30<0,0,D30-E30) -> 9614086.3 | G30: =IF(C30>'Input Data'!$B$23*12,0,D30*B30/12) -> 51229.712 | H30: =MIN(E30-G30,D30) -> 15889.409 | I30: =IF(ROUND(D30-H30,2)=0,0,D30-H30) -> 9665316
A31: =IF(('Input Data'!$C$23)="FRM", FALSE, ISNUMBER(MATCH(C31,'Input Data'!$M$18:$M$30,0))) -> FALSE | B31: =IF($A31, _xlfn.XLOOKUP(C31,'Input Data'!$M$17:$M$29,'Input Data'!$N$17:$N$29),$B30) -> 0.0635 | C31: =C30+1 -> 29 | D31: =IF(I30>0,I30-J30,0) -> 9665316 | E31: =IF('Input Data'!$E$23=0,G31,IF(OR(D31<=0,C31>'Input Data'!$B$23*12),0,IF(AND(C31='Input Data'!$B$23*12,'Input Data'!$E$23>'Input Data'!$B$23),D31+D31*B31/12,IF('Input Data'!$C$23="FRM",-PMT($B$3/12,'Input Data'!$E$23*12,$D$3),IF($A31,-PMT(B31/12,('Input Data'!$E$23*12)-C31+1,D31),E30))))) -> 67119.121 | F31: =IF(D31-E31<0,0,D31-E31) -> 9598196.9 | G31: =IF(C31>'Input Data'!$B$23*12,0,D31*B31/12) -> 51145.631 | H31: =MIN(E31-G31,D31) -> 15973.49 | I31: =IF(ROUND(D31-H31,2)=0,0,D31-H31) -> 9649342.5
A32: =IF(('Input Data'!$C$23)="FRM", FALSE, ISNUMBER(MATCH(C32,'Input Data'!$M$18:$M$30,0))) -> TRUE | B32: =IF($A32, _xlfn.XLOOKUP(C32,'Input Data'!$M$17:$M$29,'Input Data'!$N$17:$N$29),$B31) -> 0.06 | C32: =C31+1 -> 30 | D32: =IF(I31>0,I31-J31,0) -> 9649342.5 | E32: =IF('Input Data'!$E$23=0,G32,IF(OR(D32<=0,C32>'Input Data'!$B$23*12),0,IF(AND(C32='Input Data'!$B$23*12,'Input Data'!$E$23>'Input Data'!$B$23),D32+D32*B32/12,IF('Input Data'!$C$23="FRM",-PMT($B$3/12,'Input Data'!$E$23*12,$D$3),IF($A32,-PMT(B32/12,('Input Data'!$E$23*12)-C32+1,D32),E31))))) -> 65094.431 | F32: =IF(D32-E32<0,0,D32-E32) -> 9584248.1 | G32: =IF(C32>'Input Data'!$B$23*12,0,D32*B32/12) -> 48246.713 | H32: =MIN(E32-G32,D32) -> 16847.719 | I32: =IF(ROUND(D32-H32,2)=0,0,D32-H32) -> 9632494.8
A33: =IF(('Input Data'!$C$23)="FRM", FALSE, ISNUMBER(MATCH(C33,'Input Data'!$M$18:$M$30,0))) -> FALSE | B33: =IF($A33, _xlfn.XLOOKUP(C33,'Input Data'!$M$17:$M$29,'Input Data'!$N$17:$N$29),$B32) -> 0.06 | C33: =C32+1 -> 31 | D33: =IF(I32>0,I32-J32,0) -> 9632494.8 | E33: =IF('Input Data'!$E$23=0,G33,IF(OR(D33<=0,C33>'Input Data'!$B$23*12),0,IF(AND(C33='Input Data'!$B$23*12,'Input Data'!$E$23>'Input Data'!$B$23),D33+D33*B33/12,IF('Input Data'!$C$23="FRM",-PMT($B$3/12,'Input Data'!$E$23*12,$D$3),IF($A33,-PMT(B33/12,('Input Data'!$E$23*12)-C33+1,D33),E32))))) -> 65094.431 | F33: =IF(D33-E33<0,0,D33-E33) -> 9567400.4 | G33: =IF(C33>'Input Data'!$B$23*12,0,D33*B33/12) -> 48162.474 | H33: =MIN(E33-G33,D33) -> 16931.957 | I33: =IF(ROUND(D33-H33,2)=0,0,D33-H33) -> 9615562.9 | L33: PMT Calculator explained in logical steps
A34: =IF(('Input Data'!$C$23)="FRM", FALSE, ISNUMBER(MATCH(C34,'Input Data'!$M$18:$M$30,0))) -> FALSE | B34: =IF($A34, _xlfn.XLOOKUP(C34,'Input Data'!$M$17:$M$29,'Input Data'!$N$17:$N$29),$B33) -> 0.06 | C34: =C33+1 -> 32 | D34: =IF(I33>0,I33-J33,0) -> 9615562.9 | E34: =IF('Input Data'!$E$23=0,G34,IF(OR(D34<=0,C34>'Input Data'!$B$23*12),0,IF(AND(C34='Input Data'!$B$23*12,'Input Data'!$E$23>'Input Data'!$B$23),D34+D34*B34/12,IF('Input Data'!$C$23="FRM",-PMT($B$3/12,'Input Data'!$E$23*12,$D$3),IF($A34,-PMT(B34/12,('Input Data'!$E$23*12)-C34+1,D34),E33))))) -> 65094.431 | F34: =IF(D34-E34<0,0,D34-E34) -> 9550468.4 | G34: =IF(C34>'Input Data'!$B$23*12,0,D34*B34/12) -> 48077.814 | H34: =MIN(E34-G34,D34) -> 17016.617 | I34: =IF(ROUND(D34-H34,2)=0,0,D34-H34) -> 9598546.2 | L34: 1. Check if the loan is non-amortizing, and set PMT value to monthly Interest due if it is
A35: =IF(('Input Data'!$C$23)="FRM", FALSE, ISNUMBER(MATCH(C35,'Input Data'!$M$18:$M$30,0))) -> FALSE | B35: =IF($A35, _xlfn.XLOOKUP(C35,'Input Data'!$M$17:$M$29,'Input Data'!$N$17:$N$29),$B34) -> 0.06 | C35: =C34+1 -> 33 | D35: =IF(I34>0,I34-J34,0) -> 9598546.2 | E35: =IF('Input Data'!$E$23=0,G35,IF(OR(D35<=0,C35>'Input Data'!$B$23*12),0,IF(AND(C35='Input Data'!$B$23*12,'Input Data'!$E$23>'Input Data'!$B$23),D35+D35*B35/12,IF('Input Data'!$C$23="FRM",-PMT($B$3/12,'Input Data'!$E$23*12,$D$3),IF($A35,-PMT(B35/12,('Input Data'!$E$23*12)-C35+1,D35),E34))))) -> 65094.431 | F35: =IF(D35-E35<0,0,D35-E35) -> 9533451.8 | G35: =IF(C35>'Input Data'!$B$23*12,0,D35*B35/12) -> 47992.731 | H35: =MIN(E35-G35,D35) -> 17101.7 | I35: =IF(ROUND(D35-H35,2)=0,0,D35-H35) -> 9581444.5 | L35: 2. Check if the loan has been paid off or the final payment period has ended, if either is true, set the pmt to 0
A36: =IF(('Input Data'!$C$23)="FRM", FALSE, ISNUMBER(MATCH(C36,'Input Data'!$M$18:$M$30,0))) -> FALSE | B36: =IF($A36, _xlfn.XLOOKUP(C36,'Input Data'!$M$17:$M$29,'Input Data'!$N$17:$N$29),$B35) -> 0.06 | C36: =C35+1 -> 34 | D36: =IF(I35>0,I35-J35,0) -> 9581444.5 | E36: =IF('Input Data'!$E$23=0,G36,IF(OR(D36<=0,C36>'Input Data'!$B$23*12),0,IF(AND(C36='Input Data'!$B$23*12,'Input Data'!$E$23>'Input Data'!$B$23),D36+D36*B36/12,IF('Input Data'!$C$23="FRM",-PMT($B$3/12,'Input Data'!$E$23*12,$D$3),IF($A36,-PMT(B36/12,('Input Data'!$E$23*12)-C36+1,D36),E35))))) -> 65094.431 | F36: =IF(D36-E36<0,0,D36-E36) -> 9516350.1 | G36: =IF(C36>'Input Data'!$B$23*12,0,D36*B36/12) -> 47907.223 | H36: =MIN(E36-G36,D36) -> 17187.209 | I36: =IF(ROUND(D36-H36,2)=0,0,D36-H36) -> 9564257.3 | L36: 3. if the loan is in its last month of the term, check if a balloon payment is needed, and add that to the payment for the month
A37: =IF(('Input Data'!$C$23)="FRM", FALSE, ISNUMBER(MATCH(C37,'Input Data'!$M$18:$M$30,0))) -> FALSE | B37: =IF($A37, _xlfn.XLOOKUP(C37,'Input Data'!$M$17:$M$29,'Input Data'!$N$17:$N$29),$B36) -> 0.06 | C37: =C36+1 -> 35 | D37: =IF(I36>0,I36-J36,0) -> 9564257.3 | E37: =IF('Input Data'!$E$23=0,G37,IF(OR(D37<=0,C37>'Input Data'!$B$23*12),0,IF(AND(C37='Input Data'!$B$23*12,'Input Data'!$E$23>'Input Data'!$B$23),D37+D37*B37/12,IF('Input Data'!$C$23="FRM",-PMT($B$3/12,'Input Data'!$E$23*12,$D$3),IF($A37,-PMT(B37/12,('Input Data'!$E$23*12)-C37+1,D37),E36))))) -> 65094.431 | F37: =IF(D37-E37<0,0,D37-E37) -> 9499162.9 | G37: =IF(C37>'Input Data'!$B$23*12,0,D37*B37/12) -> 47821.287 | H37: =MIN(E37-G37,D37) -> 17273.145 | I37: =IF(ROUND(D37-H37,2)=0,0,D37-H37) -> 9546984.2 | L37: 4. check if loan is FRM or ARM
A38: =IF(('Input Data'!$C$23)="FRM", FALSE, ISNUMBER(MATCH(C38,'Input Data'!$M$18:$M$30,0))) -> FALSE | B38: =IF($A38, _xlfn.XLOOKUP(C38,'Input Data'!$M$17:$M$29,'Input Data'!$N$17:$N$29),$B37) -> 0.06 | C38: =C37+1 -> 36 | D38: =IF(I37>0,I37-J37,0) -> 9546984.2 | E38: =IF('Input Data'!$E$23=0,G38,IF(OR(D38<=0,C38>'Input Data'!$B$23*12),0,IF(AND(C38='Input Data'!$B$23*12,'Input Data'!$E$23>'Input Data'!$B$23),D38+D38*B38/12,IF('Input Data'!$C$23="FRM",-PMT($B$3/12,'Input Data'!$E$23*12,$D$3),IF($A38,-PMT(B38/12,('Input Data'!$E$23*12)-C38+1,D38),E37))))) -> 65094.431 | F38: =IF(D38-E38<0,0,D38-E38) -> 9481889.8 | G38: =IF(C38>'Input Data'!$B$23*12,0,D38*B38/12) -> 47734.921 | H38: =MIN(E38-G38,D38) -> 17359.51 | I38: =IF(ROUND(D38-H38,2)=0,0,D38-H38) -> 9529624.7 | L38: 5. If FRM, calculate the pmt using the given interest rate, Amortization rate, and months beginning balance for each month
A39: =IF(('Input Data'!$C$23)="FRM", FALSE, ISNUMBER(MATCH(C39,'Input Data'!$M$18:$M$30,0))) -> FALSE | B39: =IF($A39, _xlfn.XLOOKUP(C39,'Input Data'!$M$17:$M$29,'Input Data'!$N$17:$N$29),$B38) -> 0.06 | C39: =C38+1 -> 37 | D39: =IF(I38>0,I38-J38,0) -> 9529624.7 | E39: =IF('Input Data'!$E$23=0,G39,IF(OR(D39<=0,C39>'Input Data'!$B$23*12),0,IF(AND(C39='Input Data'!$B$23*12,'Input Data'!$E$23>'Input Data'!$B$23),D39+D39*B39/12,IF('Input Data'!$C$23="FRM",-PMT($B$3/12,'Input Data'!$E$23*12,$D$3),IF($A39,-PMT(B39/12,('Input Data'!$E$23*12)-C39+1,D39),E38))))) -> 65094.431 | F39: =IF(D39-E39<0,0,D39-E39) -> 9464530.3 | G39: =IF(C39>'Input Data'!$B$23*12,0,D39*B39/12) -> 47648.123 | H39: =MIN(E39-G39,D39) -> 17446.308 | I39: =IF(ROUND(D39-H39,2)=0,0,D39-H39) -> 9512178.4 | L39: 6. If ARM, each month check if the interest rate has been set to change in column A
A40: =IF(('Input Data'!$C$23)="FRM", FALSE, ISNUMBER(MATCH(C40,'Input Data'!$M$18:$M$30,0))) -> FALSE | B40: =IF($A40, _xlfn.XLOOKUP(C40,'Input Data'!$M$17:$M$29,'Input Data'!$N$17:$N$29),$B39) -> 0.06 | C40: =C39+1 -> 38 | D40: =IF(I39>0,I39-J39,0) -> 9512178.4 | E40: =IF('Input Data'!$E$23=0,G40,IF(OR(D40<=0,C40>'Input Data'!$B$23*12),0,IF(AND(C40='Input Data'!$B$23*12,'Input Data'!$E$23>'Input Data'!$B$23),D40+D40*B40/12,IF('Input Data'!$C$23="FRM",-PMT($B$3/12,'Input Data'!$E$23*12,$D$3),IF($A40,-PMT(B40/12,('Input Data'!$E$23*12)-C40+1,D40),E39))))) -> 65094.431 | F40: =IF(D40-E40<0,0,D40-E40) -> 9447083.9 | G40: =IF(C40>'Input Data'!$B$23*12,0,D40*B40/12) -> 47560.892 | H40: =MIN(E40-G40,D40) -> 17533.539 | I40: =IF(ROUND(D40-H40,2)=0,0,D40-H40) -> 9494644.8 | L40: 7. If it has changed, recalculate the pmt adjusting for the remaining months in the loan, and new interest rate
A41: =IF(('Input Data'!$C$23)="FRM", FALSE, ISNUMBER(MATCH(C41,'Input Data'!$M$18:$M$30,0))) -> FALSE | B41: =IF($A41, _xlfn.XLOOKUP(C41,'Input Data'!$M$17:$M$29,'Input Data'!$N$17:$N$29),$B40) -> 0.06 | C41: =C40+1 -> 39 | D41: =IF(I40>0,I40-J40,0) -> 9494644.8 | E41: =IF('Input Data'!$E$23=0,G41,IF(OR(D41<=0,C41>'Input Data'!$B$23*12),0,IF(AND(C41='Input Data'!$B$23*12,'Input Data'!$E$23>'Input Data'!$B$23),D41+D41*B41/12,IF('Input Data'!$C$23="FRM",-PMT($B$3/12,'Input Data'!$E$23*12,$D$3),IF($A41,-PMT(B41/12,('Input Data'!$E$23*12)-C41+1,D41),E40))))) -> 65094.431 | F41: =IF(D41-E41<0,0,D41-E41) -> 9429550.4 | G41: =IF(C41>'Input Data'!$B$23*12,0,D41*B41/12) -> 47473.224 | H41: =MIN(E41-G41,D41) -> 17621.207 | I41: =IF(ROUND(D41-H41,2)=0,0,D41-H41) -> 9477023.6 | L41: 8. if the rate has not changed, repeat the same payment as the previous month
...

Sheet Property Pro Forma Financials
C4: Trailing 12 Months | D4: Year 1 Financials | E4: Year 2 Financials | F4: Year 3 Financials | G4: Year 4 Financials | I4: Year 5 (For Forward Cap Rate Only) | M4: Exit Cap Rate
B5: Income | M5: ='Input Data'!E17 -> 0.065
B6: Gross Potential Rent | C6: ='Input Data'!$C$8*12*'Input Data'!$D$3 -> 1728000 | D6: =C6*(1+'Input Data'!$H$8) -> 1775520 | E6: =D6*(1+'Input Data'!$H$8) -> 1824346.8 | F6: =E6*(1+'Input Data'!$H$8) -> 1874516.3 | G6: =F6*(1+'Input Data'!$H$8) -> 1926065.5 | I6: =G6*(1+'Input Data'!$H$8) -> 1979032.3
B7: Vacancy Loss | C7: =-(C6*'Input Data'!$D$8) -> -120960 | D7: =-(D6*'Input Data'!$D$8) -> -124286.4 | E7: =-(E6*'Input Data'!$D$8) -> -127704.28 | F7: =-(F6*'Input Data'!$D$8) -> -131216.14 | G7: =-(G6*'Input Data'!$D$8) -> -134824.59 | I7: =-(I6*'Input Data'!$D$8) -> -138532.26 | M7: Exit Price at exit cap rate and year 5 NOI
B8: Effective Rental Income | C8: =C6+C7 -> 1607040 | D8: =D6+D7 -> 1651233.6 | E8: =E6+E7 -> 1696642.5 | F8: =F6+F7 -> 1743300.2 | G8: =G6+G7 -> 1791240.9 | I8: =I6+I7 -> 1840500.1 | M8: =I25/M5 -> 17581513
B9: Other Income | C9: =C6*'Input Data'!$E$8 -> 51840 | D9: =D6*'Input Data'!$E$8 -> 53265.6 | E9: =E6*'Input Data'!$E$8 -> 54730.404 | F9: =F6*'Input Data'!$E$8 -> 56235.49 | G9: =G6*'Input Data'!$E$8 -> 57781.966 | I9: =I6*'Input Data'!$E$8 -> 59370.97
B10: Effective Gross Income | C10: =C8+C9 -> 1658880 | D10: =D8+D9 -> 1704499.2 | E10: =E8+E9 -> 1751372.9 | F10: =F8+F9 -> 1799535.7 | G10: =G8+G9 -> 1849022.9 | I10: =I8+I9 -> 1899871
B12: Expenses
B13: Repairs & Maintenance | C13: =C10*'Input Data'!$B$12 -> 99532.8 | D13: =D10*'Input Data'!$B$12 -> 102269.95 | E13: =E10*'Input Data'!$B$12 -> 105082.38 | F13: =F10*'Input Data'!$B$12 -> 107972.14 | G13: =G10*'Input Data'!$B$12 -> 110941.37 | I13: =I10*'Input Data'!$B$12 -> 113992.26
B14: Payroll & Admin | C14: =C10*'Input Data'!$C$12 -> 82944 | D14: =D10*'Input Data'!$C$12 -> 85224.96 | E14: =E10*'Input Data'!$C$12 -> 87568.646 | F14: =F10*'Input Data'!$C$12 -> 89976.784 | G14: =G10*'Input Data'!$C$12 -> 92451.146 | I14: =I10*'Input Data'!$C$12 -> 94993.552
B15: Utilities | C15: =C10*'Input Data'!$D$12 -> 124416 | D15: =D10*'Input Data'!$D$12 -> 127837.44 | E15: =E10*'Input Data'!$D$12 -> 131352.97 | F15: =F10*'Input Data'!$D$12 -> 134965.18 | G15: =G10*'Input Data'!$D$12 -> 138676.72 | I15: =I10*'Input Data'!$D$12 -> 142490.33
B16: Management Fees | C16: =C10*'Input Data'!$E$12 -> 82944 | D16: =D10*'Input Data'!$E$12 -> 85224.96 | E16: =E10*'Input Data'!$E$12 -> 87568.646 | F16: =F10*'Input Data'!$E$12 -> 89976.784 | G16: =G10*'Input Data'!$E$12 -> 92451.146 | I16: =I10*'Input Data'!$E$12 -> 94993.552
B17: Variable Expenses | C17: =SUM(C13:C16) -> 389836.8 | D17: =SUM(D13:D16) -> 400557.31 | E17: =SUM(E13:E16) -> 411572.64 | F17: =SUM(F13:F16) -> 422890.89 | G17: =SUM(G13:G16) -> 434520.38 | I17: =SUM(I13:I16) -> 446469.7 | L17: Per Unit expense growth
L18: 0.025
B19: Insurance | C19: ='Input Data'!$H$12*'Input Data'!$D$3 -> 40800 | D19: =C19*(1+$L$18) -> 41820 | E19: =D19*(1+$L$18) -> 42865.5 | F19: =E19*(1+$L$18) -> 43937.137 | G19: =F19*(1+$L$18) -> 45035.566 | I19: =G19*(1+$L$18) -> 46161.455
B20: Replacement Reserves | C20: ='Input Data'!$I$12*'Input Data'!$D$3 -> 28800 | D20: =C20*(1+$L$18) -> 29520 | E20: =D20*(1+$L$18) -> 30258 | F20: =E20*(1+$L$18) -> 31014.45 | G20: =F20*(1+$L$18) -> 31789.811 | I20: =G20*(1+$L$18) -> 32584.557
B21: Fixed Per Unit Expenses | C21: =SUM(C19:C20) -> 69600 | D21: =SUM(D19:D20) -> 71340 | E21: =SUM(E19:E20) -> 73123.5 | F21: =SUM(F19:F20) -> 74951.587 | G21: =SUM(G19:G20) -> 76825.377 | I21: =SUM(I19:I20) -> 78746.012 | L21: Tax Expense Growth Rate
L22: 0.02
B23: Taxes | C23: ='Input Data'!$F$12*'Input Data'!$B$17 -> 210000 | D23: =C23*(1+$L$22) -> 214200 | E23: =D23*(1+$L$22) -> 218484 | F23: =E23*(1+$L$22) -> 222853.68 | G23: =F23*(1+$L$22) -> 227310.75 | I23: =G23*(1+$L$22) -> 231856.97
B25: Net Operating Income | C25: =C10-C17-C21-C23 -> 989443.2 | D25: =D10-D17-D21-D23 -> 1018401.9 | E25: =E10-E17-E21-E23 -> 1048192.8 | F25: =F10-F17-F21-F23 -> 1078839.5 | G25: =G10-G17-G21-G23 -> 1110366.4 | I25: =I10-I17-I21-I23 -> 1142798.4
B27: Debt Service | C27: =SUM('Debt calculations'!E3:E14) -> 805429.45 | D27: =SUM('Debt calculations'!E15:E26) -> 805429.45 | E27: =SUM('Debt calculations'!E27:E38) -> 791256.62 | F27: =SUM('Debt calculations'!E39:E50) -> 781133.18 | G27: =SUM('Debt calculations'!E51:E62) -> 781133.18 | I27: =SUM('Debt calculations'!F51:F62) -> 1.0974876e+08
B29: Maximum Loan for property | C29: ='Input Data'!C27*'Input Data'!B17 -> 10920000
B30: DSCR | C30: =C25/C27 -> 1.2284666 | D30: =D25/D27 -> 1.264421 | E30: =E25/E27 -> 1.3247191 | F30: =F25/F27 -> 1.3811211 | G30: =G25/G27 -> 1.4214816
B31: Cap Rate | C31: =C25/'Input Data'!$B$17 -> 0.058895429 | D31: =D25/'Input Data'!$B$17 -> 0.06061916 | E31: =E25/'Input Data'!$B$17 -> 0.062392428 | F31: =F25/'Input Data'!$B$17 -> 0.064216639 | G31: =G25/'Input Data'!$B$17 -> 0.066093238
B35: ='Input Data'!B25 -> Limits On Loan
B36: ='Input Data'!B26 -> Minimum DSCR | C36: ='Input Data'!C26 -> Maximum LTV | D36: ='Input Data'!D26 -> Minimum Debt Yield
B37: ='Input Data'!B27 -> 1.25 | C37: ='Input Data'!C27 -> 0.65 | D37: ='Input Data'!D27 -> 0.0875

Sheet Final Analysis
C2: Loan Details
C3: Loan Amount | D3: ='Input Data'!B17*(1-'Input Data'!C17) -> 10080000
C4: Monthly Payment (ignoring interest rate changes) | D4: ='Debt calculations'!E3 -> 67119.121
C5: Annual Payments (monthly payment * 12) | D5: =D4*12 -> 805429.45
C6: Balloon Payment | D6: ='Debt calculations'!M10 -> 2204814.5
C10: Property Income
C11: Gross Potential Rent (historic) | D11: ='Property Pro Forma Financials'!C6 -> 1728000
C12: Net Operating Income | D12: ='Property Pro Forma Financials'!C25 -> 989443.2
C21: Total Debt Service for year 1 | D21: =SUM('Debt calculations'!G3:G14)*(1-'Input Data'!K12)+SUM('Debt calculations'!H3:H14) -> 665689.47
C23: Maximum Loan for property | D23: ='Input Data'!C27*'Input Data'!B17 -> 10920000
C24: Property DSCR | D24: =D12/D21 -> 1.4863435
C25: Property LTV | D25: =D3/'Input Data'!J3 -> 0.6
C26: Property Debt Yield | D26: =D12/D3 -> 0.098159048

Sheet Stress Test Inputs
A1: Stress Test Inputs | B1: Property Overview
A2: The values from Property Overview through Acquisition Assumptions are referenced directly from the sheet "Input Data" but can be altered without impacting all sheets colored green without harm to the original model | B2: Property Name | C2: Property Type | D2: Units | E2: Year Built | F2: Occupancy rate | G2: Market | I2: Average Unit Side | J2: Appraised Value | M2: Custom Amort and Loan Length Inputs
B3: ='Input Data'!B3 -> Test Property 1 | C3: ='Input Data'!C3 -> Garden Style Multifamily | D3: ='Input Data'!D3 -> 96 | E3: ='Input Data'!E3 -> 1998 | F3: ='Input Data'!F3 -> 0.93 | G3: ='Input Data'!G3 -> Secondary metro, growing pop | I3: ='Input Data'!I3 -> 900 Sq Ft | J3: ='Input Data'!J3 -> 16800000 | M3: Select Custom Inputs in B25 and E25 to enable
M4: Custom Loan Length (Years) | N4: ='Input Data'!N4 -> 22
M5: Custom Amortization Period (Years) | N5: ='Input Data'!N5 -> 25
B6: Income Assumptions
B7: Average In-place rent | C7: Market Rent | D7: Economic Vacancy | E7: Other income (as a % of gross potential rent) | H7: Annual rent growth
B8: ='Input Data'!B8 -> 1425 | C8: ='Input Data'!C8 -> 1500 | D8: ='Input Data'!D8 -> 0.07 | E8: ='Input Data'!E8 -> 0.03 | H8: ='Input Data'!H8 -> 0.0275
B10: Operating Expenses | D10: As a % of EGI | H10: $ Per unit per year
B11: Reparis & maintenance | C11: payroll & admin | D11: Utilities | E11: management fee | F11: Property taxes (as a % of purchase price) | H11: insurance | I11: replacement reserves | K11: Tax Rate
B12: ='Input Data'!B12 -> 0.06 | C12: ='Input Data'!C12 -> 0.05 | D12: ='Input Data'!D12 -> 0.075 | E12: ='Input Data'!E12 -> 0.05 | F12: ='Input Data'!F12 -> 0.0125 | H12: ='Input Data'!H12 -> 425 | I12: ='Input Data'!I12 -> 300 | K12: ='Input Data'!K12 -> 0.22 | M12: ARM Mode Enabled?
M13: Green = Yes Red = No
B15: Acquisition assumptions
B16: Purchase Price (including fees) | C16: Down Payment | M16: ARM Rate Adjustments
B17: ='Input Data'!B17 -> 16800000 | C17: ='Input Data'!C17 -> 0.4 | M17: Month of adjustment | N17: New annual rate
M18: =IF('Input Data'!M18=0,"",'Input Data'!M18) -> 30 | N18: =IF('Input Data'!N18=0,"",'Input Data'!N18) -> 0.06
M19: =IF('Input Data'!M19=0,"",'Input Data'!M19) | N19: =IF('Input Data'!N19=0,"",'Input Data'!N19)
M20: =IF('Input Data'!M20=0,"",'Input Data'!M20) | N20: =IF('Input Data'!N20=0,"",'Input Data'!N20)
B21: Debt Terms | M21: =IF('Input Data'!M21=0,"",'Input Data'!M21) | N21: =IF('Input Data'!N21=0,"",'Input Data'!N21)
A22: Values In debt terms and Limits on loan are not referenced directly from "Input Data" to allow for easier stress testing | B22: Loan Length | C22: Fixed or Adjustable rate | D22: Interest Rate (annual) | E22: Amortization Length | M22: =IF('Input Data'!M22=0,"",'Input Data'!M22) | N22: =IF('Input Data'!N22=0,"",'Input Data'!N22)
B23: 10 | C23: ARM | D23: 0.0635 | E23: =$N$5 -> 25 | M23: =IF('Input Data'!M23=0,"",'Input Data'!M23) | N23: =IF('Input Data'!N23=0,"",'Input Data'!N23)
M24: =IF('Input Data'!M24=0,"",'Input Data'!M24) | N24: =IF('Input Data'!N24=0,"",'Input Data'!N24)
B25: Limits On Loan | M25: =IF('Input Data'!M25=0,"",'Input Data'!M25) | N25: =IF('Input Data'!N25=0,"",'Input Data'!N25)
B26: Minimum DSCR | C26: Maximum LTV | D26: Minimum Debt Yield | M26: =IF('Input Data'!M26=0,"",'Input Data'!M26) | N26: =IF('Input Data'!N26=0,"",'Input Data'!N26)
B27: 1.25 | C27: 0.65 | D27: 0.0875 | M27: =IF('Input Data'!M27=0,"",'Input Data'!M27) | N27: =IF('Input Data'!N27=0,"",'Input Data'!N27)
M28: =IF('Input Data'!M28=0,"",'Input Data'!M28) | N28: =IF('Input Data'!N28=0,"",'Input Data'!N28)
M29: =IF('Input Data'!M29=0,"",'Input Data'!M29) | N29: =IF('Input Data'!N29=0,"",'Input Data'!N29)
M30: =IF('Input Data'!M30=0,"",'Input Data'!M30) | N30: =IF('Input Data'!N30=0,"",'Input Data'!N30)

Sheet Stress Test Debt Calc
B1: Stress Test Debt
A2: ARM Adjustment check | B2: Interest rate | C2: month | D2: Beginning Balance | E2: PMT | F2: After pmt mortgage amount | G2: Interest amount | H2: Principal paid | I2: End of Month Balance | J2: Prepayment of Loan In $ (manual input to adjust for prepayment of loan)
A3: =IF(('Stress Test Inputs'!$C$23)="FRM", FALSE, ISNUMBER(MATCH(C3,'Stress Test Inputs'!$M$18:$M$30,0))) -> FALSE | B3: ='Stress Test Inputs'!$D$23+'Stress Test Financial Analysis'!D5 -> 0.0635 | C3: 1 | D3: ='Stress Test Inputs'!B17*(1-'Stress Test Inputs'!C17) -> 10080000 | E3: =IF(OR(D3<=0,C3>'Stress Test Inputs'!$B$23*12),0,IF(AND(C3='Stress Test Inputs'!$B$23*12,'Stress Test Inputs'!$E$23>'Stress Test Inputs'!$B$23),D3+D3*B3/12,IF('Stress Test Inputs'!$C$23="FRM",-PMT($B$3/12,'Stress Test Inputs'!$E$23*12,$D$3),IF($A3,-PMT(B3/12,('Stress Test Inputs'!$E$23*12)-C3+1,D3),-PMT(B3/12,'Stress Test Inputs'!E23*12,'Stress Test Debt Calc'!D3))))) -> 67119.121 | F3: =IF(D3-E3<0,0,D3-E3) -> 10012881 | G3: =IF(C3>'Stress Test Inputs'!$B$23*12,0,D3*B3/12) -> 53340 | H3: =MIN(E3-G3,D3) -> 13779.121 | I3: =IF(ROUND(D3-H3,2)=0,0,D3-H3) -> 10066221
A4: =IF(('Stress Test Inputs'!$C$23)="FRM", FALSE, ISNUMBER(MATCH(C4,'Stress Test Inputs'!$M$18:$M$30,0))) -> FALSE | B4: =IF($A4, (_xlfn.XLOOKUP(C4,'Stress Test Inputs'!$M$17:$M$29,'Stress Test Inputs'!$N$17:$N$29)+'Stress Test Financial Analysis'!$D$5),$B3) -> 0.0635 | C4: =C3+1 -> 2 | D4: =IF(I3>0,I3-J3,0) -> 10066221 | E4: =IF(OR(D4<=0,C4>'Stress Test Inputs'!$B$23*12),0,IF(AND(C4='Stress Test Inputs'!$B$23*12,'Stress Test Inputs'!$E$23>'Stress Test Inputs'!$B$23),D4+D4*B4/12,IF('Stress Test Inputs'!$C$23="FRM",-PMT($B$3/12,'Stress Test Inputs'!$E$23*12,$D$3),IF($A4,-PMT(B4/12,('Stress Test Inputs'!$E$23*12)-C4+1,D4),E3)))) -> 67119.121 | F4: =IF(D4-E4<0,0,D4-E4) -> 9999101.8 | G4: =IF(C4>'Stress Test Inputs'!$B$23*12,0,D4*B4/12) -> 53267.085 | H4: =MIN(E4-G4,D4) -> 13852.035 | I4: =IF(ROUND(D4-H4,2)=0,0,D4-H4) -> 10052369
A5: =IF(('Stress Test Inputs'!$C$23)="FRM", FALSE, ISNUMBER(MATCH(C5,'Stress Test Inputs'!$M$18:$M$30,0))) -> FALSE | B5: =IF($A5, (_xlfn.XLOOKUP(C5,'Stress Test Inputs'!$M$17:$M$29,'Stress Test Inputs'!$N$17:$N$29)+'Stress Test Financial Analysis'!$D$5),$B4) -> 0.0635 | C5: =C4+1 -> 3 | D5: =IF(I4>0,I4-J4,0) -> 10052369 | E5: =IF(OR(D5<=0,C5>'Stress Test Inputs'!$B$23*12),0,IF(AND(C5='Stress Test Inputs'!$B$23*12,'Stress Test Inputs'!$E$23>'Stress Test Inputs'!$B$23),D5+D5*B5/12,IF('Stress Test Inputs'!$C$23="FRM",-PMT($B$3/12,'Stress Test Inputs'!$E$23*12,$D$3),IF($A5,-PMT(B5/12,('Stress Test Inputs'!$E$23*12)-C5+1,D5),E4)))) -> 67119.121 | F5: =IF(D5-E5<0,0,D5-E5) -> 9985249.7 | G5: =IF(C5>'Stress Test Inputs'!$B$23*12,0,D5*B5/12) -> 53193.785 | H5: =MIN(E5-G5,D5) -> 13925.336 | I5: =IF(ROUND(D5-H5,2)=0,0,D5-H5) -> 10038444
A6: =IF(('Stress Test Inputs'!$C$23)="FRM", FALSE, ISNUMBER(MATCH(C6,'Stress Test Inputs'!$M$18:$M$30,0))) -> FALSE | B6: =IF($A6, (_xlfn.XLOOKUP(C6,'Stress Test Inputs'!$M$17:$M$29,'Stress Test Inputs'!$N$17:$N$29)+'Stress Test Financial Analysis'!$D$5),$B5) -> 0.0635 | C6: =C5+1 -> 4 | D6: =IF(I5>0,I5-J5,0) -> 10038444 | E6: =IF(OR(D6<=0,C6>'Stress Test Inputs'!$B$23*12),0,IF(AND(C6='Stress Test Inputs'!$B$23*12,'Stress Test Inputs'!$E$23>'Stress Test Inputs'!$B$23),D6+D6*B6/12,IF('Stress Test Inputs'!$C$23="FRM",-PMT($B$3/12,'Stress Test Inputs'!$E$23*12,$D$3),IF($A6,-PMT(B6/12,('Stress Test Inputs'!$E$23*12)-C6+1,D6),E5)))) -> 67119.121 | F6: =IF(D6-E6<0,0,D6-E6) -> 9971324.4 | G6: =IF(C6>'Stress Test Inputs'!$B$23*12,0,D6*B6/12) -> 53120.097 | H6: =MIN(E6-G6,D6) -> 13999.024 | I6: =IF(ROUND(D6-H6,2)=0,0,D6-H6) -> 10024444
A7: =IF(('Stress Test Inputs'!$C$23)="FRM", FALSE, ISNUMBER(MATCH(C7,'Stress Test Inputs'!$M$18:$M$30,0))) -> FALSE | B7: =IF($A7, (_xlfn.XLOOKUP(C7,'Stress Test Inputs'!$M$17:$M$29,'Stress Test Inputs'!$N$17:$N$29)+'Stress Test Financial Analysis'!$D$5),$B6) -> 0.0635 | C7: =C6+1 -> 5 | D7: =IF(I6>0,I6-J6,0) -> 10024444 | E7: =IF(OR(D7<=0,C7>'Stress Test Inputs'!$B$23*12),0,IF(AND(C7='Stress Test Inputs'!$B$23*12,'Stress Test Inputs'!$E$23>'Stress Test Inputs'!$B$23),D7+D7*B7/12,IF('Stress Test Inputs'!$C$23="FRM",-PMT($B$3/12,'Stress Test Inputs'!$E$23*12,$D$3),IF($A7,-PMT(B7/12,('Stress Test Inputs'!$E$23*12)-C7+1,D7),E6)))) -> 67119.121 | F7: =IF(D7-E7<0,0,D7-E7) -> 9957325.4 | G7: =IF(C7>'Stress Test Inputs'!$B$23*12,0,D7*B7/12) -> 53046.019 | H7: =MIN(E7-G7,D7) -> 14073.102 | I7: =IF(ROUND(D7-H7,2)=0,0,D7-H7) -> 10010371
A8: =IF(('Stress Test Inputs'!$C$23)="FRM", FALSE, ISNUMBER(MATCH(C8,'Stress Test Inputs'!$M$18:$M$30,0))) -> FALSE | B8: =IF($A8, (_xlfn.XLOOKUP(C8,'Stress Test Inputs'!$M$17:$M$29,'Stress Test Inputs'!$N$17:$N$29)+'Stress Test Financial Analysis'!$D$5),$B7) -> 0.0635 | C8: =C7+1 -> 6 | D8: =IF(I7>0,I7-J7,0) -> 10010371 | E8: =IF(OR(D8<=0,C8>'Stress Test Inputs'!$B$23*12),0,IF(AND(C8='Stress Test Inputs'!$B$23*12,'Stress Test Inputs'!$E$23>'Stress Test Inputs'!$B$23),D8+D8*B8/12,IF('Stress Test Inputs'!$C$23="FRM",-PMT($B$3/12,'Stress Test Inputs'!$E$23*12,$D$3),IF($A8,-PMT(B8/12,('Stress Test Inputs'!$E$23*12)-C8+1,D8),E7)))) -> 67119.121 | F8: =IF(D8-E8<0,0,D8-E8) -> 9943252.3 | G8: =IF(C8>'Stress Test Inputs'!$B$23*12,0,D8*B8/12) -> 52971.549 | H8: =MIN(E8-G8,D8) -> 14147.572 | I8: =IF(ROUND(D8-H8,2)=0,0,D8-H8) -> 9996223.8
A9: =IF(('Stress Test Inputs'!$C$23)="FRM", FALSE, ISNUMBER(MATCH(C9,'Stress Test Inputs'!$M$18:$M$30,0))) -> FALSE | B9: =IF($A9, (_xlfn.XLOOKUP(C9,'Stress Test Inputs'!$M$17:$M$29,'Stress Test Inputs'!$N$17:$N$29)+'Stress Test Financial Analysis'!$D$5),$B8) -> 0.0635 | C9: =C8+1 -> 7 | D9: =IF(I8>0,I8-J8,0) -> 9996223.8 | E9: =IF(OR(D9<=0,C9>'Stress Test Inputs'!$B$23*12),0,IF(AND(C9='Stress Test Inputs'!$B$23*12,'Stress Test Inputs'!$E$23>'Stress Test Inputs'!$B$23),D9+D9*B9/12,IF('Stress Test Inputs'!$C$23="FRM",-PMT($B$3/12,'Stress Test Inputs'!$E$23*12,$D$3),IF($A9,-PMT(B9/12,('Stress Test Inputs'!$E$23*12)-C9+1,D9),E8)))) -> 67119.121 | F9: =IF(D9-E9<0,0,D9-E9) -> 9929104.7 | G9: =IF(C9>'Stress Test Inputs'!$B$23*12,0,D9*B9/12) -> 52896.684 | H9: =MIN(E9-G9,D9) -> 14222.437 | I9: =IF(ROUND(D9-H9,2)=0,0,D9-H9) -> 9982001.4 | L9: Loan Maturity Month | M9: =12*'Stress Test Inputs'!B23 -> 120
A10: =IF(('Stress Test Inputs'!$C$23)="FRM", FALSE, ISNUMBER(MATCH(C10,'Stress Test Inputs'!$M$18:$M$30,0))) -> FALSE | B10: =IF($A10, (_xlfn.XLOOKUP(C10,'Stress Test Inputs'!$M$17:$M$29,'Stress Test Inputs'!$N$17:$N$29)+'Stress Test Financial Analysis'!$D$5),$B9) -> 0.0635 | C10: =C9+1 -> 8 | D10: =IF(I9>0,I9-J9,0) -> 9982001.4 | E10: =IF(OR(D10<=0,C10>'Stress Test Inputs'!$B$23*12),0,IF(AND(C10='Stress Test Inputs'!$B$23*12,'Stress Test Inputs'!$E$23>'Stress Test Inputs'!$B$23),D10+D10*B10/12,IF('Stress Test Inputs'!$C$23="FRM",-PMT($B$3/12,'Stress Test Inputs'!$E$23*12,$D$3),IF($A10,-PMT(B10/12,('Stress Test Inputs'!$E$23*12)-C10+1,D10),E9)))) -> 67119.121 | F10: =IF(D10-E10<0,0,D10-E10) -> 9914882.3 | G10: =IF(C10>'Stress Test Inputs'!$B$23*12,0,D10*B10/12) -> 52821.424 | H10: =MIN(E10-G10,D10) -> 14297.697 | I10: =IF(ROUND(D10-H10,2)=0,0,D10-H10) -> 9967703.7 | L10: Balloon Payment | M10: =IF('Stress Test Inputs'!$E$23<='Stress Test Inputs'!$B$23,"No Balloon Payment",_xlfn.XLOOKUP(M9,C3:C362,E3:E362,"Value Not Found")) -> 7779013.3
A11: =IF(('Stress Test Inputs'!$C$23)="FRM", FALSE, ISNUMBER(MATCH(C11,'Stress Test Inputs'!$M$18:$M$30,0))) -> FALSE | B11: =IF($A11, (_xlfn.XLOOKUP(C11,'Stress Test Inputs'!$M$17:$M$29,'Stress Test Inputs'!$N$17:$N$29)+'Stress Test Financial Analysis'!$D$5),$B10) -> 0.0635 | C11: =C10+1 -> 9 | D11: =IF(I10>0,I10-J10,0) -> 9967703.7 | E11: =IF(OR(D11<=0,C11>'Stress Test Inputs'!$B$23*12),0,IF(AND(C11='Stress Test Inputs'!$B$23*12,'Stress Test Inputs'!$E$23>'Stress Test Inputs'!$B$23),D11+D11*B11/12,IF('Stress Test Inputs'!$C$23="FRM",-PMT($B$3/12,'Stress Test Inputs'!$E$23*12,$D$3),IF($A11,-PMT(B11/12,('Stress Test Inputs'!$E$23*12)-C11+1,D11),E10)))) -> 67119.121 | F11: =IF(D11-E11<0,0,D11-E11) -> 9900584.6 | G11: =IF(C11>'Stress Test Inputs'!$B$23*12,0,D11*B11/12) -> 52745.765 | H11: =MIN(E11-G11,D11) -> 14373.356 | I11: =IF(ROUND(D11-H11,2)=0,0,D11-H11) -> 9953330.3
A12: =IF(('Stress Test Inputs'!$C$23)="FRM", FALSE, ISNUMBER(MATCH(C12,'Stress Test Inputs'!$M$18:$M$30,0))) -> FALSE | B12: =IF($A12, (_xlfn.XLOOKUP(C12,'Stress Test Inputs'!$M$17:$M$29,'Stress Test Inputs'!$N$17:$N$29)+'Stress Test Financial Analysis'!$D$5),$B11) -> 0.0635 | C12: =C11+1 -> 10 | D12: =IF(I11>0,I11-J11,0) -> 9953330.3 | E12: =IF(OR(D12<=0,C12>'Stress Test Inputs'!$B$23*12),0,IF(AND(C12='Stress Test Inputs'!$B$23*12,'Stress Test Inputs'!$E$23>'Stress Test Inputs'!$B$23),D12+D12*B12/12,IF('Stress Test Inputs'!$C$23="FRM",-PMT($B$3/12,'Stress Test Inputs'!$E$23*12,$D$3),IF($A12,-PMT(B12/12,('Stress Test Inputs'!$E$23*12)-C12+1,D12),E11)))) -> 67119.121 | F12: =IF(D12-E12<0,0,D12-E12) -> 9886211.2 | G12: =IF(C12>'Stress Test Inputs'!$B$23*12,0,D12*B12/12) -> 52669.706 | H12: =MIN(E12-G12,D12) -> 14449.415 | I12: =IF(ROUND(D12-H12,2)=0,0,D12-H12) -> 9938880.9
A13: =IF(('Stress Test Inputs'!$C$23)="FRM", FALSE, ISNUMBER(MATCH(C13,'Stress Test Inputs'!$M$18:$M$30,0))) -> FALSE | B13: =IF($A13, (_xlfn.XLOOKUP(C13,'Stress Test Inputs'!$M$17:$M$29,'Stress Test Inputs'!$N$17:$N$29)+'Stress Test Financial Analysis'!$D$5),$B12) -> 0.0635 | C13: =C12+1 -> 11 | D13: =IF(I12>0,I12-J12,0) -> 9938880.9 | E13: =IF(OR(D13<=0,C13>'Stress Test Inputs'!$B$23*12),0,IF(AND(C13='Stress Test Inputs'!$B$23*12,'Stress Test Inputs'!$E$23>'Stress Test Inputs'!$B$23),D13+D13*B13/12,IF('Stress Test Inputs'!$C$23="FRM",-PMT($B$3/12,'Stress Test Inputs'!$E$23*12,$D$3),IF($A13,-PMT(B13/12,('Stress Test Inputs'!$E$23*12)-C13+1,D13),E12)))) -> 67119.121 | F13: =IF(D13-E13<0,0,D13-E13) -> 9871761.8 | G13: =IF(C13>'Stress Test Inputs'!$B$23*12,0,D13*B13/12) -> 52593.245 | H13: =MIN(E13-G13,D13) -> 14525.876 | I13: =IF(ROUND(D13-H13,2)=0,0,D13-H13) -> 9924355
A14: =IF(('Stress Test Inputs'!$C$23)="FRM", FALSE, ISNUMBER(MATCH(C14,'Stress Test Inputs'!$M$18:$M$30,0))) -> FALSE | B14: =IF($A14, (_xlfn.XLOOKUP(C14,'Stress Test Inputs'!$M$17:$M$29,'Stress Test Inputs'!$N$17:$N$29)+'Stress Test Financial Analysis'!$D$5),$B13) -> 0.0635 | C14: =C13+1 -> 12 | D14: =IF(I13>0,I13-J13,0) -> 9924355 | E14: =IF(OR(D14<=0,C14>'Stress Test Inputs'!$B$23*12),0,IF(AND(C14='Stress Test Inputs'!$B$23*12,'Stress Test Inputs'!$E$23>'Stress Test Inputs'!$B$23),D14+D14*B14/12,IF('Stress Test Inputs'!$C$23="FRM",-PMT($B$3/12,'Stress Test Inputs'!$E$23*12,$D$3),IF($A14,-PMT(B14/12,('Stress Test Inputs'!$E$23*12)-C14+1,D14),E13)))) -> 67119.121 | F14: =IF(D14-E14<0,0,D14-E14) -> 9857235.9 | G14: =IF(C14>'Stress Test Inputs'!$B$23*12,0,D14*B14/12) -> 52516.379 | H14: =MIN(E14-G14,D14) -> 14602.742 | I14: =IF(ROUND(D14-H14,2)=0,0,D14-H14) -> 9909752.3
A15: =IF(('Stress Test Inputs'!$C$23)="FRM", FALSE, ISNUMBER(MATCH(C15,'Stress Test Inputs'!$M$18:$M$30,0))) -> FALSE | B15: =IF($A15, (_xlfn.XLOOKUP(C15,'Stress Test Inputs'!$M$17:$M$29,'Stress Test Inputs'!$N$17:$N$29)+'Stress Test Financial Analysis'!$D$5),$B14) -> 0.0635 | C15: =C14+1 -> 13 | D15: =IF(I14>0,I14-J14,0) -> 9909752.3 | E15: =IF(OR(D15<=0,C15>'Stress Test Inputs'!$B$23*12),0,IF(AND(C15='Stress Test Inputs'!$B$23*12,'Stress Test Inputs'!$E$23>'Stress Test Inputs'!$B$23),D15+D15*B15/12,IF('Stress Test Inputs'!$C$23="FRM",-PMT($B$3/12,'Stress Test Inputs'!$E$23*12,$D$3),IF($A15,-PMT(B15/12,('Stress Test Inputs'!$E$23*12)-C15+1,D15),E14)))) -> 67119.121 | F15: =IF(D15-E15<0,0,D15-E15) -> 9842633.2 | G15: =IF(C15>'Stress Test Inputs'!$B$23*12,0,D15*B15/12) -> 52439.106 | H15: =MIN(E15-G15,D15) -> 14680.015 | I15: =IF(ROUND(D15-H15,2)=0,0,D15-H15) -> 9895072.3
A16: =IF(('Stress Test Inputs'!$C$23)="FRM", FALSE, ISNUMBER(MATCH(C16,'Stress Test Inputs'!$M$18:$M$30,0))) -> FALSE | B16: =IF($A16, (_xlfn.XLOOKUP(C16,'Stress Test Inputs'!$M$17:$M$29,'Stress Test Inputs'!$N$17:$N$29)+'Stress Test Financial Analysis'!$D$5),$B15) -> 0.0635 | C16: =C15+1 -> 14 | D16: =IF(I15>0,I15-J15,0) -> 9895072.3 | E16: =IF(OR(D16<=0,C16>'Stress Test Inputs'!$B$23*12),0,IF(AND(C16='Stress Test Inputs'!$B$23*12,'Stress Test Inputs'!$E$23>'Stress Test Inputs'!$B$23),D16+D16*B16/12,IF('Stress Test Inputs'!$C$23="FRM",-PMT($B$3/12,'Stress Test Inputs'!$E$23*12,$D$3),IF($A16,-PMT(B16/12,('Stress Test Inputs'!$E$23*12)-C16+1,D16),E15)))) -> 67119.121 | F16: =IF(D16-E16<0,0,D16-E16) -> 9827953.2 | G16: =IF(C16>'Stress Test Inputs'!$B$23*12,0,D16*B16/12) -> 52361.424 | H16: =MIN(E16-G16,D16) -> 14757.697 | I16: =IF(ROUND(D16-H16,2)=0,0,D16-H16) -> 9880314.6
A17: =IF(('Stress Test Inputs'!$C$23)="FRM", FALSE, ISNUMBER(MATCH(C17,'Stress Test Inputs'!$M$18:$M$30,0))) -> FALSE | B17: =IF($A17, (_xlfn.XLOOKUP(C17,'Stress Test Inputs'!$M$17:$M$29,'Stress Test Inputs'!$N$17:$N$29)+'Stress Test Financial Analysis'!$D$5),$B16) -> 0.0635 | C17: =C16+1 -> 15 | D17: =IF(I16>0,I16-J16,0) -> 9880314.6 | E17: =IF(OR(D17<=0,C17>'Stress Test Inputs'!$B$23*12),0,IF(AND(C17='Stress Test Inputs'!$B$23*12,'Stress Test Inputs'!$E$23>'Stress Test Inputs'!$B$23),D17+D17*B17/12,IF('Stress Test Inputs'!$C$23="FRM",-PMT($B$3/12,'Stress Test Inputs'!$E$23*12,$D$3),IF($A17,-PMT(B17/12,('Stress Test Inputs'!$E$23*12)-C17+1,D17),E16)))) -> 67119.121 | F17: =IF(D17-E17<0,0,D17-E17) -> 9813195.5 | G17: =IF(C17>'Stress Test Inputs'!$B$23*12,0,D17*B17/12) -> 52283.331 | H17: =MIN(E17-G17,D17) -> 14835.79 | I17: =IF(ROUND(D17-H17,2)=0,0,D17-H17) -> 9865478.8
A18: =IF(('Stress Test Inputs'!$C$23)="FRM", FALSE, ISNUMBER(MATCH(C18,'Stress Test Inputs'!$M$18:$M$30,0))) -> FALSE | B18: =IF($A18, (_xlfn.XLOOKUP(C18,'Stress Test Inputs'!$M$17:$M$29,'Stress Test Inputs'!$N$17:$N$29)+'Stress Test Financial Analysis'!$D$5),$B17) -> 0.0635 | C18: =C17+1 -> 16 | D18: =IF(I17>0,I17-J17,0) -> 9865478.8 | E18: =IF(OR(D18<=0,C18>'Stress Test Inputs'!$B$23*12),0,IF(AND(C18='Stress Test Inputs'!$B$23*12,'Stress Test Inputs'!$E$23>'Stress Test Inputs'!$B$23),D18+D18*B18/12,IF('Stress Test Inputs'!$C$23="FRM",-PMT($B$3/12,'Stress Test Inputs'!$E$23*12,$D$3),IF($A18,-PMT(B18/12,('Stress Test Inputs'!$E$23*12)-C18+1,D18),E17)))) -> 67119.121 | F18: =IF(D18-E18<0,0,D18-E18) -> 9798359.7 | G18: =IF(C18>'Stress Test Inputs'!$B$23*12,0,D18*B18/12) -> 52204.825 | H18: =MIN(E18-G18,D18) -> 14914.296 | I18: =IF(ROUND(D18-H18,2)=0,0,D18-H18) -> 9850564.5
A19: =IF(('Stress Test Inputs'!$C$23)="FRM", FALSE, ISNUMBER(MATCH(C19,'Stress Test Inputs'!$M$18:$M$30,0))) -> FALSE | B19: =IF($A19, (_xlfn.XLOOKUP(C19,'Stress Test Inputs'!$M$17:$M$29,'Stress Test Inputs'!$N$17:$N$29)+'Stress Test Financial Analysis'!$D$5),$B18) -> 0.0635 | C19: =C18+1 -> 17 | D19: =IF(I18>0,I18-J18,0) -> 9850564.5 | E19: =IF(OR(D19<=0,C19>'Stress Test Inputs'!$B$23*12),0,IF(AND(C19='Stress Test Inputs'!$B$23*12,'Stress Test Inputs'!$E$23>'Stress Test Inputs'!$B$23),D19+D19*B19/12,IF('Stress Test Inputs'!$C$23="FRM",-PMT($B$3/12,'Stress Test Inputs'!$E$23*12,$D$3),IF($A19,-PMT(B19/12,('Stress Test Inputs'!$E$23*12)-C19+1,D19),E18)))) -> 67119.121 | F19: =IF(D19-E19<0,0,D19-E19) -> 9783445.4 | G19: =IF(C19>'Stress Test Inputs'!$B$23*12,0,D19*B19/12) -> 52125.904 | H19: =MIN(E19-G19,D19) -> 14993.217 | I19: =IF(ROUND(D19-H19,2)=0,0,D19-H19) -> 9835571.3
